Workbook

Sheet Game Description
A1: About the Game
A2: Game Name | B2: Burning classic | H2: • 20 line game left-to-right evaluation
A3: Game Type | B3: 20 lines | H3: • Wins are formed by matching symbols on consecutive reels starting from reel 1
A4: Window Size (Base Game) | B4: 3X5 | H4: only >=3 of kind combination is paid
A5: Pay Direction | B5: Left to Right | H5: Free spins can be retriggered. Retrigger gives 10 free spins
A6: Total Bet Range | H6: If 3OK of Wild has less pay than 3OK Wild plus Symbol , then symbol's 4OK is paid and similar case for 4OK wild.
A7: Buy multiplier | B7: 50x
A14: Symbols Table | C14: 3OK | D14: 4OK | E14: 5OK
A15: HV1 | B15: AA | C15: 20 | D15: 100 | E15: 200
A16: HV2 | B16: BB | C16: 20 | D16: 100 | E16: 200
A17: HV3 | B17: CC | C17: 20 | D17: 100 | E17: 200
A18: LV1 | B18: DD | C18: 5 | D18: 20 | E18: 100
A19: LV2 | B19: EE | C19: 5 | D19: 20 | E19: 100
A20: LV3 | B20: FF | C20: 1 | D20: 10 | E20: 50
A21: LV4 | B21: GG | C21: 1 | D21: 10 | E21: 50
A22: Wild | B22: WD | C22: 40 | D22: 400 | E22: 1000
A23: Scatter | B23: SC | C23: 10 | D23: 50 | E23: 500
A26: Line | B26: Reel 1 | C26: Reel 2 | D26: Reel 3 | E26: Reel 4 | F26: Reel 5
A27: 1 | B27: 1 | C27: 1 | D27: 1 | E27: 1 | F27: 1
A28: 2 | B28: 0 | C28: 0 | D28: 0 | E28: 0 | F28: 0
A29: 3 | B29: 2 | C29: 2 | D29: 2 | E29: 2 | F29: 2
A30: 4 | B30: 0 | C30: 1 | D30: 2 | E30: 1 | F30: 0
A31: 5 | B31: 2 | C31: 1 | D31: 0 | E31: 1 | F31: 2
A32: 6 | B32: 0 | C32: 0 | D32: 1 | E32: 0 | F32: 0
A33: 7 | B33: 2 | C33: 2 | D33: 1 | E33: 2 | F33: 2
A34: 8 | B34: 1 | C34: 2 | D34: 2 | E34: 2 | F34: 1
A35: 9 | B35: 1 | C35: 0 | D35: 0 | E35: 0 | F35: 1
A36: 10 | B36: 1 | C36: 0 | D36: 1 | E36: 0 | F36: 1
A37: 11 | B37: 1 | C37: 2 | D37: 1 | E37: 2 | F37: 1
A38: 12 | B38: 0 | C38: 1 | D38: 0 | E38: 1 | F38: 0
... A46: 20 | B46: 0 | C46: 2 | D46: 0 | E46: 2 | F46: 0

Sheet Parsheet
H2: Base Game Stats | L2: Win Brackets
H3: Base game Hitrate | I3: 3.06643 | L3: Win | M3: Frequency (%) | N3: Count
B4: Base bet | C4: 20 | L4: 0x | M4: 67.3888
L5: 0-1x | M5: 17.7783
B6: Base game RTP | C6: 57.7172 | E6: Max win cap | F6: 22000 | H6: Free game Stats | L6: 1 - 2x | M6: 7.2106
B7: Free Game RTP | C7: 37.4294 | E7: max win hitrate | F7: 12 | H7: Free game Trigger Rate | I7: 69.8411 | L7: 2 - 3x | M7: 2.8829
E8: Simulation count | F8: 1000000000 | H8: Free game Hitrate | I8: 2.02609 | L8: 3 - 5x | M8: 1.1048
B9: Total | C9: =SUM(C6:C7) -> 95.1466 | L9: 5 - 10x | M9: 1.7417
H10: Average Free spins : | I10: 12.247 | L10: 10 - 20x | M10: 0.8838
H11: Average Wins : | I11: 26.153X | L11: 20-50x | M11: 0.7068
H12: Retrigger rate : | I12: 54.5048 | L12: 50-100x | M12: 0.2575
L13: 100-200x | M13: 0.0402
H14: Buy free spin | L14: 200-300x | M14: 0.0015
H15: Average Win | I15: 47.489x | L15: 300-500x | M15: 0.0001
L16: 500-600x | N16: 5
L17: 600+ | M17: 0.0031

Sheet BaseGameReel
B1: Basegame Reel Strip
A2: Reel 1 | B2: Reel 2 | C2: Reel 3 | D2: Reel 4 | E2: Reel 5
A3: GG | B3: EE | C3: FF | D3: EE | E3: EE | Q3: Base bet | R3: 20
A4: GG | B4: EE | C4: FF | D4: GG | E4: EE
A5: EE | B5: EE | C5: AA | D5: EE | E5: EE | O5: Symbol | P5: Number | Q5: Payout | R5: Reel 1 | S5: Reel 2 | T5: Reel 3 | U5: Reel 4 | V5: Reel 5 | X5: Hits | Y5: RTP | AA5: Symbol | AB5: Symbols | AC5: Number | AD5: Payout | AE5: Reel 1 | AF5: Reel 2 | AG5: Reel 3 | AH5: Reel 4 | AI5: Reel 5 | AK5: Hits | AL5: RTP
A6: AA | B6: AA | C6: EE | D6: EE | E6: BB | O6: AA | P6: 5 | Q6: ='Game Description'!E15 -> 200 | R6: =INDEX($H$11:$L$19,MATCH($O6,$G$11:$G$18,0),MATCH(R$5,$H$10:$L$10,0))+H$19 -> 5 | S6: =INDEX($H$11:$L$19,MATCH($O6,$G$11:$G$18,0),MATCH(S$5,$H$10:$L$10,0))+I$19 -> 6 | T6: =INDEX($H$11:$L$19,MATCH($O6,$G$11:$G$18,0),MATCH(T$5,$H$10:$L$10,0))+J$19 -> 8 | U6: =INDEX($H$11:$L$19,MATCH($O6,$G$11:$G$18,0),MATCH(U$5,$H$10:$L$10,0))+K$19 -> 6 | V6: =INDEX($H$11:$L$19,MATCH($O6,$G$11:$G$18,0),MATCH(V$5,$H$10:$L$10,0))+L$19 -> 6 | W6: =X6*Q6 -> 1705600 | X6: =PRODUCT(R6:V6)-AK6-AK8-AK27 -> 8528 | Y6: =(X6/$X$43)*Q6 -> 0.00545792 | AA6: WD | AB6: AA | AC6: 4 | AD6: ='Game Description'!$D$22 -> 400 | AE6: =INDEX($H$11:$L$19,MATCH($AA6,$G$11:$G$19,0),MATCH(R$5,$H$10:$L$10,0)) -> 1 | AF6: =INDEX($H$11:$L$19,MATCH($AA6,$G$11:$G$19,0),MATCH(S$5,$H$10:$L$10,0)) -> 2 | AG6: =INDEX($H$11:$L$19,MATCH($AA6,$G$11:$G$19,0),MATCH(T$5,$H$10:$L$10,0)) -> 2 | AH6: =INDEX($H$11:$L$19,MATCH($AA6,$G$11:$G$19,0),MATCH(U$5,$H$10:$L$10,0)) -> 2 | AI6: =INDEX($H$11:$L$19,MATCH("AA",$G$11:$G$19,0),MATCH(AI$5,$H$10:$L$10,0)) -> 4 | AJ6: =AL6*$X$43 -> 12800 | AK6: =PRODUCT(AE6:AI6) -> 32 | AL6: =IF(AD6>Q6,AD6,Q6)*(AK6/$X$43) -> 4.096e-05
A7: BB | B7: AA | C7: GG | D7: SC | E7: EE | O7: AA | P7: 4 | Q7: ='Game Description'!D15 -> 100 | R7: =INDEX($H$11:$L$19,MATCH($O7,$G$11:$G$18,0),MATCH(R$5,$H$10:$L$10,0))+H$19 -> 5 | S7: =INDEX($H$11:$L$19,MATCH($O7,$G$11:$G$18,0),MATCH(S$5,$H$10:$L$10,0))+I$19 -> 6 | T7: =INDEX($H$11:$L$19,MATCH($O7,$G$11:$G$18,0),MATCH(T$5,$H$10:$L$10,0))+J$19 -> 8 | U7: =INDEX($H$11:$L$19,MATCH($O7,$G$11:$G$18,0),MATCH(U$5,$H$10:$L$10,0))+K$19 -> 6 | V7: =L$20-(L$19+INDEX($H$11:$L$19,MATCH($O7,$G$11:$G$17,0),MATCH(V$5,$H$10:$L$10,0))) -> 44 | W7: =X7*Q7 -> 6230400 | X7: =PRODUCT(R7:V7)-PRODUCT($H$19:$K$19)*$V7-$AK7 -> 62304 | Y7: =(X7/$X$43)*Q7 -> 0.01993728 | AA7: WD | AB7: AA | AC7: 3 | AD7: ='Game Description'!$C$22 -> 40 | AE7: =INDEX($H$11:$L$19,MATCH($AA7,$G$11:$G$19,0),MATCH(R$5,$H$10:$L$10,0)) -> 1 | AF7: =INDEX($H$11:$L$19,MATCH($AA7,$G$11:$G$19,0),MATCH(S$5,$H$10:$L$10,0)) -> 2 | AG7: =INDEX($H$11:$L$19,MATCH($AA7,$G$11:$G$19,0),MATCH(T$5,$H$10:$L$10,0)) -> 2 | AH7: =INDEX($H$11:$L$19,MATCH("AA",$G$11:$G$19,0),MATCH(AH$5,$H$10:$L$10,0)) -> 4 | AI7: =$L$20-L$19-L11 -> 44 | AJ7: =AL7*$X$43 -> 70400 | AK7: =PRODUCT(AE7:AI7) -> 704 | AL7: =IF(AD7>Q7,AD7,Q7)*(AK7/$X$43) -> 0.00022528
A8: BB | B8: GG | C8: SC | D8: BB | E8: CC | O8: AA | P8: 3 | Q8: ='Game Description'!C15 -> 20 | R8: =INDEX($H$11:$L$19,MATCH($O8,$G$11:$G$18,0),MATCH(R$5,$H$10:$L$10,0))+H$19 -> 5 | S8: =INDEX($H$11:$L$19,MATCH($O8,$G$11:$G$18,0),MATCH(S$5,$H$10:$L$10,0))+I$19 -> 6 | T8: =INDEX($H$11:$L$19,MATCH($O8,$G$11:$G$18,0),MATCH(T$5,$H$10:$L$10,0))+J$19 -> 8 | U8: =K$20-(K$19+INDEX($H$11:$L$19,MATCH($O8,$G$11:$G$18,0),MATCH(U$5,$H$10:$L$10,0))) -> 44 | V8: =$L$20 -> 50 | W8: =X8*Q8 -> 10384000 | X8: =PRODUCT(R8:V8)- PRODUCT($H$19:$J$19)*U8*V8 -> 519200 | Y8: =(X8/$X$43)*Q8 -> 0.0332288 | AA8: WD | AB8: AA | AC8: 3 | AD8: ='Game Description'!$C$22 -> 40 | AE8: =INDEX($H$11:$L$19,MATCH($AA8,$G$11:$G$19,0),MATCH(R$5,$H$10:$L$10,0)) -> 1 | AF8: =INDEX($H$11:$L$19,MATCH($AA8,$G$11:$G$19,0),MATCH(S$5,$H$10:$L$10,0)) -> 2 | AG8: =INDEX($H$11:$L$19,MATCH($AA8,$G$11:$G$19,0),MATCH(T$5,$H$10:$L$10,0)) -> 2 | AH8: =INDEX($H$11:$L$19,MATCH("AA",$G$11:$G$19,0),MATCH(AH$5,$H$10:$L$10,0)) -> 4 | AI8: =L11 -> 4 | AJ8: =AL8*$X$43 -> 12800 | AK8: =PRODUCT(AE8:AI8) -> 64 | AL8: =IF(AD8>Q6,AD8,Q6)*(AK8/$X$43) -> 4.096e-05
A9: EE | B9: CC | C9: BB | D9: EE | E9: FF | G9: With | O9: BB | P9: 5 | Q9: ='Game Description'!E16 -> 200 | R9: =INDEX($H$11:$L$19,MATCH($O9,$G$11:$G$18,0),MATCH(R$5,$H$10:$L$10,0))+H$19 -> 6 | S9: =INDEX($H$11:$L$19,MATCH($O9,$G$11:$G$18,0),MATCH(S$5,$H$10:$L$10,0))+I$19 -> 7 | T9: =INDEX($H$11:$L$19,MATCH($O9,$G$11:$G$18,0),MATCH(T$5,$H$10:$L$10,0))+J$19 -> 6 | U9: =INDEX($H$11:$L$19,MATCH($O9,$G$11:$G$18,0),MATCH(U$5,$H$10:$L$10,0))+K$19 -> 5 | V9: =INDEX($H$11:$L$19,MATCH($O9,$G$11:$G$18,0),MATCH(V$5,$H$10:$L$10,0))+L$19 -> 6 | W9: =X9*Q9 -> 1492800 | X9: =PRODUCT(R9:V9)-AK9-AK11-AK27 -> 7464 | Y9: =(X9/$X$43)*Q9 -> 0.00477696 | Z9: =SUM(Y6:Y8) -> 0.058624 | AA9: WD | AB9: BB | AC9: 4 | AD9: ='Game Description'!$D$22 -> 400 | AE9: =INDEX($H$11:$L$19,MATCH($AA9,$G$11:$G$19,0),MATCH(R$5,$H$10:$L$10,0)) -> 1 | AF9: =INDEX($H$11:$L$19,MATCH($AA9,$G$11:$G$19,0),MATCH(S$5,$H$10:$L$10,0)) -> 2 | AG9: =INDEX($H$11:$L$19,MATCH($AA9,$G$11:$G$19,0),MATCH(T$5,$H$10:$L$10,0)) -> 2 | AH9: =INDEX($H$11:$L$19,MATCH($AA9,$G$11:$G$19,0),MATCH(U$5,$H$10:$L$10,0)) -> 2 | AI9: =INDEX($H$11:$L$19,MATCH("BB",$G$11:$G$19,0),MATCH(AI$5,$H$10:$L$10,0)) -> 4 | AJ9: =AL9*$X$43 -> 12800 | AK9: =PRODUCT(AE9:AI9) -> 32 | AL9: =IF(AD9>Q9,AD9,Q9)*(AK9/$X$43) -> 4.096e-05
A10: AA | B10: EE | C10: FF | D10: DD | E10: EE | G10: Symbol | H10: Reel 1 | I10: Reel 2 | J10: Reel 3 | K10: Reel 4 | L10: Reel 5 | O10: BB | P10: 4 | Q10: ='Game Description'!D16 -> 100 | R10: =INDEX($H$11:$L$19,MATCH($O10,$G$11:$G$18,0),MATCH(R$5,$H$10:$L$10,0))+H$19 -> 6 | S10: =INDEX($H$11:$L$19,MATCH($O10,$G$11:$G$18,0),MATCH(S$5,$H$10:$L$10,0))+I$19 -> 7 | T10: =INDEX($H$11:$L$19,MATCH($O10,$G$11:$G$18,0),MATCH(T$5,$H$10:$L$10,0))+J$19 -> 6 | U10: =INDEX($H$11:$L$19,MATCH($O10,$G$11:$G$18,0),MATCH(U$5,$H$10:$L$10,0))+K$19 -> 5 | V10: =L$20-(L$19+INDEX($H$11:$L$19,MATCH($O10,$G$11:$G$17,0),MATCH(V$5,$H$10:$L$10,0))) -> 44 | W10: =X10*Q10 -> 5456000 | X10: =PRODUCT(R10:V10)-PRODUCT($H$19:$K$19)*$V10-$AK10 -> 54560 | Y10: =(X10/$X$43)*Q10 -> 0.0174592 | AA10: WD | AB10: BB | AC10: 3 | AD10: ='Game Description'!$C$22 -> 40 | AE10: =INDEX($H$11:$L$19,MATCH($AA10,$G$11:$G$19,0),MATCH(R$5,$H$10:$L$10,0)) -> 1 | AF10: =INDEX($H$11:$L$19,MATCH($AA10,$G$11:$G$19,0),MATCH(S$5,$H$10:$L$10,0)) -> 2 | AG10: =INDEX($H$11:$L$19,MATCH($AA10,$G$11:$G$19,0),MATCH(T$5,$H$10:$L$10,0)) -> 2 | AH10: =INDEX($H$11:$L$19,MATCH("BB",$G$11:$G$19,0),MATCH(AH$5,$H$10:$L$10,0)) -> 3 | AI10: =$L$20-L$19-L12 -> 44 | AJ10: =AL10*$X$43 -> 52800 | AK10: =PRODUCT(AE10:AI10) -> 528 | AL10: =IF(AD10>Q10,AD10,Q10)*(AK10/$X$43) -> 0.00016896
A11: GG | B11: SC | C11: CC | D11: GG | E11: SC | G11: AA | H11: =COUNTIF(A$1:A$899,$G11) -> 4 | I11: =COUNTIF(B$1:B$899,$G11) -> 4 | J11: =COUNTIF(C$1:C$899,$G11) -> 6 | K11: =COUNTIF(D$1:D$899,$G11) -> 4 | L11: =COUNTIF(E$1:E$899,$G11) -> 4 | O11: BB | P11: 3 | Q11: ='Game Description'!C16 -> 20 | R11: =INDEX($H$11:$L$19,MATCH($O11,$G$11:$G$18,0),MATCH(R$5,$H$10:$L$10,0))+H$19 -> 6 | S11: =INDEX($H$11:$L$19,MATCH($O11,$G$11:$G$18,0),MATCH(S$5,$H$10:$L$10,0))+I$19 -> 7 | T11: =INDEX($H$11:$L$19,MATCH($O11,$G$11:$G$18,0),MATCH(T$5,$H$10:$L$10,0))+J$19 -> 6 | U11: =K$20-(K$19+INDEX($H$11:$L$19,MATCH($O11,$G$11:$G$18,0),MATCH(U$5,$H$10:$L$10,0))) -> 45 | V11: =$L$20 -> 50 | W11: =X11*Q11 -> 11160000 | X11: =PRODUCT(R11:V11)- PRODUCT($H$19:$J$19)*U11*V11 -> 558000 | Y11: =X11/$X$43*Q11 -> 0.035712 | AA11: WD | AB11: BB | AC11: 3 | AD11: ='Game Description'!$C$22 -> 40 | AE11: =INDEX($H$11:$L$19,MATCH($AA11,$G$11:$G$19,0),MATCH(R$5,$H$10:$L$10,0)) -> 1 | AF11: =INDEX($H$11:$L$19,MATCH($AA11,$G$11:$G$19,0),MATCH(S$5,$H$10:$L$10,0)) -> 2 | AG11: =INDEX($H$11:$L$19,MATCH($AA11,$G$11:$G$19,0),MATCH(T$5,$H$10:$L$10,0)) -> 2 | AH11: =INDEX($H$11:$L$19,MATCH("BB",$G$11:$G$19,0),MATCH(AH$5,$H$10:$L$10,0)) -> 3 | AI11: =L12 -> 4 | AJ11: =AL11*$X$43 -> 9600 | AK11: =PRODUCT(AE11:AI11) -> 48 | AL11: =IF(AD11>Q9,AD11,Q9)*(AK11/$X$43) -> 3.072e-05
A12: DD | B12: AA | C12: AA | D12: CC | E12: GG | G12: BB | H12: =COUNTIF(A$1:A$899,$G12) -> 5 | I12: =COUNTIF(B$1:B$899,$G12) -> 5 | J12: =COUNTIF(C$1:C$899,$G12) -> 4 | K12: =COUNTIF(D$1:D$899,$G12) -> 3 | L12: =COUNTIF(E$1:E$899,$G12) -> 4 | O12: CC | P12: 5 | Q12: ='Game Description'!E17 -> 200 | R12: =INDEX($H$11:$L$19,MATCH($O12,$G$11:$G$18,0),MATCH(R$5,$H$10:$L$10,0))+H$19 -> 5 | S12: =INDEX($H$11:$L$19,MATCH($O12,$G$11:$G$18,0),MATCH(S$5,$H$10:$L$10,0))+I$19 -> 7 | T12: =INDEX($H$11:$L$19,MATCH($O12,$G$11:$G$18,0),MATCH(T$5,$H$10:$L$10,0))+J$19 -> 5 | U12: =INDEX($H$11:$L$19,MATCH($O12,$G$11:$G$18,0),MATCH(U$5,$H$10:$L$10,0))+K$19 -> 6 | V12: =INDEX($H$11:$L$19,MATCH($O12,$G$11:$G$18,0),MATCH(V$5,$H$10:$L$10,0))+L$19 -> 7 | W12: =X12*Q12 -> 1442800 | X12: =PRODUCT(R12:V12)-AK12-AK14-AK27 -> 7214 | Y12: =(X12/$X$43)*Q12 -> 0.00461696 | Z12: =SUM(Y9:Y11) -> 0.05794816 | AA12: WD | AB12: CC | AC12: 4 | AD12: ='Game Description'!$D$22 -> 400 | AE12: =INDEX($H$11:$L$19,MATCH($AA12,$G$11:$G$19,0),MATCH(R$5,$H$10:$L$10,0)) -> 1 | AF12: =INDEX($H$11:$L$19,MATCH($AA12,$G$11:$G$19,0),MATCH(S$5,$H$10:$L$10,0)) -> 2 | AG12: =INDEX($H$11:$L$19,MATCH($AA12,$G$11:$G$19,0),MATCH(T$5,$H$10:$L$10,0)) -> 2 | AH12: =INDEX($H$11:$L$19,MATCH($AA12,$G$11:$G$19,0),MATCH(U$5,$H$10:$L$10,0)) -> 2 | AI12: =INDEX($H$11:$L$19,MATCH("CC",$G$11:$G$19,0),MATCH(AI$5,$H$10:$L$10,0)) -> 5 | AJ12: =AL12*$X$43 -> 16000 | AK12: =PRODUCT(AE12:AI12) -> 40 | AL12: =IF(AD12>Q12,AD12,Q12)*(AK12/$X$43) -> 5.12e-05
A13: FF | B13: FF | C13: AA | D13: WD | E13: DD | G13: CC | H13: =COUNTIF(A$1:A$899,$G13) -> 4 | I13: =COUNTIF(B$1:B$899,$G13) -> 5 | J13: =COUNTIF(C$1:C$899,$G13) -> 3 | K13: =COUNTIF(D$1:D$899,$G13) -> 4 | L13: =COUNTIF(E$1:E$899,$G13) -> 5 | O13: CC | P13: 4 | Q13: ='Game Description'!D17 -> 100 | R13: =INDEX($H$11:$L$19,MATCH($O13,$G$11:$G$18,0),MATCH(R$5,$H$10:$L$10,0))+H$19 -> 5 | S13: =INDEX($H$11:$L$19,MATCH($O13,$G$11:$G$18,0),MATCH(S$5,$H$10:$L$10,0))+I$19 -> 7 | T13: =INDEX($H$11:$L$19,MATCH($O13,$G$11:$G$18,0),MATCH(T$5,$H$10:$L$10,0))+J$19 -> 5 | U13: =INDEX($H$11:$L$19,MATCH($O13,$G$11:$G$18,0),MATCH(U$5,$H$10:$L$10,0))+K$19 -> 6 | V13: =L$20-(L$19+INDEX($H$11:$L$19,MATCH($O13,$G$11:$G$17,0),MATCH(V$5,$H$10:$L$10,0))) -> 43 | W13: =X13*Q13 -> 4411800 | X13: =PRODUCT(R13:V13)-PRODUCT($H$19:$K$19)*$V13-$AK13 -> 44118 | Y13: =(X13/$X$43)*Q13 -> 0.01411776 | AA13: WD | AB13: CC | AC13: 3 | AD13: ='Game Description'!$C$22 -> 40 | AE13: =INDEX($H$11:$L$19,MATCH($AA13,$G$11:$G$19,0),MATCH(R$5,$H$10:$L$10,0)) -> 1 | AF13: =INDEX($H$11:$L$19,MATCH($AA13,$G$11:$G$19,0),MATCH(S$5,$H$10:$L$10,0)) -> 2 | AG13: =INDEX($H$11:$L$19,MATCH($AA13,$G$11:$G$19,0),MATCH(T$5,$H$10:$L$10,0)) -> 2 | AH13: =INDEX($H$11:$L$19,MATCH("CC",$G$11:$G$19,0),MATCH(AH$5,$H$10:$L$10,0)) -> 4 | AI13: =$L$20-L$19-L13 -> 43 | AJ13: =AL13*$X$43 -> 68800 | AK13: =PRODUCT(AE13:AI13) -> 688 | AL13: =IF(AD13>Q13,AD13,Q13)*(AK13/$X$43) -> 0.00022016
A14: BB | B14: FF | C14: AA | D14: GG | E14: FF | G14: DD | H14: =COUNTIF(A$1:A$899,$G14) -> 7 | I14: =COUNTIF(B$1:B$899,$G14) -> 6 | J14: =COUNTIF(C$1:C$899,$G14) -> 8 | K14: =COUNTIF(D$1:D$899,$G14) -> 8 | L14: =COUNTIF(E$1:E$899,$G14) -> 7 | O14: CC | P14: 3 | Q14: ='Game Description'!C17 -> 20 | R14: =INDEX($H$11:$L$19,MATCH($O14,$G$11:$G$18,0),MATCH(R$5,$H$10:$L$10,0))+H$19 -> 5 | S14: =INDEX($H$11:$L$19,MATCH($O14,$G$11:$G$18,0),MATCH(S$5,$H$10:$L$10,0))+I$19 -> 7 | T14: =INDEX($H$11:$L$19,MATCH($O14,$G$11:$G$18,0),MATCH(T$5,$H$10:$L$10,0))+J$19 -> 5 | U14: =K$20-(K$19+INDEX($H$11:$L$19,MATCH($O14,$G$11:$G$18,0),MATCH(U$5,$H$10:$L$10,0))) -> 44 | V14: =$L$20 -> 50 | W14: =X14*Q14 -> 7524000 | X14: =PRODUCT(R14:V14)- PRODUCT($H$19:$J$19)*U14*V14 -> 376200 | Y14: =(X14/$X$43)*Q14 -> 0.0240768 | AA14: WD | AB14: CC | AC14: 3 | AD14: ='Game Description'!$C$22 -> 40 | AE14: =INDEX($H$11:$L$19,MATCH($AA14,$G$11:$G$19,0),MATCH(R$5,$H$10:$L$10,0)) -> 1 | AF14: =INDEX($H$11:$L$19,MATCH($AA14,$G$11:$G$19,0),MATCH(S$5,$H$10:$L$10,0)) -> 2 | AG14: =INDEX($H$11:$L$19,MATCH($AA14,$G$11:$G$19,0),MATCH(T$5,$H$10:$L$10,0)) -> 2 | AH14: =INDEX($H$11:$L$19,MATCH("CC",$G$11:$G$19,0),MATCH(AH$5,$H$10:$L$10,0)) -> 4 | AI14: =L13 -> 5 | AJ14: =AL14*$X$43 -> 16000 | AK14: =PRODUCT(AE14:AI14) -> 80 | AL14: =IF(AD14>Q12,AD14,Q12)*(AK14/$X$43) -> 5.12e-05
A15: SC | B15: GG | C15: BB | D15: GG | E15: GG | G15: EE | H15: =COUNTIF(A$1:A$899,$G15) -> 7 | I15: =COUNTIF(B$1:B$899,$G15) -> 7 | J15: =COUNTIF(C$1:C$899,$G15) -> 6 | K15: =COUNTIF(D$1:D$899,$G15) -> 8 | L15: =COUNTIF(E$1:E$899,$G15) -> 8 | O15: DD | P15: 5 | Q15: ='Game Description'!E18 -> 100 | R15: =INDEX($H$11:$L$19,MATCH($O15,$G$11:$G$18,0),MATCH(R$5,$H$10:$L$10,0))+H$19 -> 8 | S15: =INDEX($H$11:$L$19,MATCH($O15,$G$11:$G$18,0),MATCH(S$5,$H$10:$L$10,0))+I$19 -> 8 | T15: =INDEX($H$11:$L$19,MATCH($O15,$G$11:$G$18,0),MATCH(T$5,$H$10:$L$10,0))+J$19 -> 10 | U15: =INDEX($H$11:$L$19,MATCH($O15,$G$11:$G$18,0),MATCH(U$5,$H$10:$L$10,0))+K$19 -> 10 | V15: =INDEX($H$11:$L$19,MATCH($O15,$G$11:$G$18,0),MATCH(V$5,$H$10:$L$10,0))+L$19 -> 9 | W15: =X15*Q15 -> 5730400 | X15: =PRODUCT(R15:V15)-AK15-AK17-AK27 -> 57304 | Y15: =(X15/$X$43)*Q15 -> 0.01833728 | Z15: =SUM(Y12:Y14) -> 0.04281152 | AA15: WD | AB15: DD | AC15: 4 | AD15: ='Game Description'!$D$22 -> 400 | AE15: =INDEX($H$11:$L$19,MATCH($AA15,$G$11:$G$19,0),MATCH(R$5,$H$10:$L$10,0)) -> 1 | AF15: =INDEX($H$11:$L$19,MATCH($AA15,$G$11:$G$19,0),MATCH(S$5,$H$10:$L$10,0)) -> 2 | AG15: =INDEX($H$11:$L$19,MATCH($AA15,$G$11:$G$19,0),MATCH(T$5,$H$10:$L$10,0)) -> 2 | AH15: =INDEX($H$11:$L$19,MATCH($AA15,$G$11:$G$19,0),MATCH(U$5,$H$10:$L$10,0)) -> 2 | AI15: =INDEX($H$11:$L$19,MATCH("DD",$G$11:$G$19,0),MATCH(AI$5,$H$10:$L$10,0)) -> 7 | AJ15: =AL15*$X$43 -> 22400 | AK15: =PRODUCT(AE15:AI15) -> 56 | AL15: =IF(AD15>Q15,AD15,Q15)*(AK15/$X$43) -> 7.168e-05
A16: DD | B16: GG | C16: CC | D16: EE | E16: WD | G16: FF | H16: =COUNTIF(A$1:A$899,$G16) -> 10 | I16: =COUNTIF(B$1:B$899,$G16) -> 8 | J16: =COUNTIF(C$1:C$899,$G16) -> 10 | K16: =COUNTIF(D$1:D$899,$G16) -> 10 | L16: =COUNTIF(E$1:E$899,$G16) -> 10 | O16: DD | P16: 4 | Q16: ='Game Description'!D18 -> 20 | R16: =INDEX($H$11:$L$19,MATCH($O16,$G$11:$G$18,0),MATCH(R$5,$H$10:$L$10,0))+H$19 -> 8 | S16: =INDEX($H$11:$L$19,MATCH($O16,$G$11:$G$18,0),MATCH(S$5,$H$10:$L$10,0))+I$19 -> 8 | T16: =INDEX($H$11:$L$19,MATCH($O16,$G$11:$G$18,0),MATCH(T$5,$H$10:$L$10,0))+J$19 -> 10 | U16: =INDEX($H$11:$L$19,MATCH($O16,$G$11:$G$18,0),MATCH(U$5,$H$10:$L$10,0))+K$19 -> 10 | V16: =L$20-(L$19+INDEX($H$11:$L$19,MATCH($O16,$G$11:$G$17,0),MATCH(V$5,$H$10:$L$10,0))) -> 41 | W16: =X16*Q16 -> 5215200 | X16: =PRODUCT(R16:V16)-PRODUCT($H$19:$K$19)*$V16-$AK16 -> 260760 | Y16: =(X16/$X$43)*Q16 -> 0.01668864 | AA16: WD | AB16: DD | AC16: 3 | AD16: ='Game Description'!$C$22 -> 40 | AE16: =INDEX($H$11:$L$19,MATCH($AA16,$G$11:$G$19,0),MATCH(R$5,$H$10:$L$10,0)) -> 1 | AF16: =INDEX($H$11:$L$19,MATCH($AA16,$G$11:$G$19,0),MATCH(S$5,$H$10:$L$10,0)) -> 2 | AG16: =INDEX($H$11:$L$19,MATCH($AA16,$G$11:$G$19,0),MATCH(T$5,$H$10:$L$10,0)) -> 2 | AH16: =INDEX($H$11:$L$19,MATCH("DD",$G$11:$G$19,0),MATCH(AH$5,$H$10:$L$10,0)) -> 8 | AI16: =$L$20-L$19-L14 -> 41 | AJ16: =AL16*$X$43 -> 52480 | AK16: =PRODUCT(AE16:AI16) -> 1312 | AL16: =IF(AD16>Q16,AD16,Q16)*(AK16/$X$43) -> 0.000167936
A17: DD | B17: CC | C17: AA | D17: GG | E17: DD | G17: GG | H17: =COUNTIF(A$1:A$899,$G17) -> 10 | I17: =COUNTIF(B$1:B$899,$G17) -> 11 | J17: =COUNTIF(C$1:C$899,$G17) -> 9 | K17: =COUNTIF(D$1:D$899,$G17) -> 9 | L17: =COUNTIF(E$1:E$899,$G17) -> 8 | O17: DD | P17: 3 | Q17: ='Game Description'!C18 -> 5 | R17: =INDEX($H$11:$L$19,MATCH($O17,$G$11:$G$18,0),MATCH(R$5,$H$10:$L$10,0))+H$19 -> 8 | S17: =INDEX($H$11:$L$19,MATCH($O17,$G$11:$G$18,0),MATCH(S$5,$H$10:$L$10,0))+I$19 -> 8 | T17: =INDEX($H$11:$L$19,MATCH($O17,$G$11:$G$18,0),MATCH(T$5,$H$10:$L$10,0))+J$19 -> 10 | U17: =K$20-(K$19+INDEX($H$11:$L$19,MATCH($O17,$G$11:$G$18,0),MATCH(U$5,$H$10:$L$10,0))) -> 40 | V17: =$L$20 -> 50 | W17: =X17*Q17 -> 6360000 | X17: =PRODUCT(R17:V17)- PRODUCT($H$19:$J$19)*U17*V17 -> 1272000 | Y17: =(X17/$X$43)*Q17 -> 0.020352 | AA17: WD | AB17: DD | AC17: 3 | AD17: ='Game Description'!$C$22 -> 40 | AE17: =INDEX($H$11:$L$19,MATCH($AA17,$G$11:$G$19,0),MATCH(R$5,$H$10:$L$10,0)) -> 1 | AF17: =INDEX($H$11:$L$19,MATCH($AA17,$G$11:$G$19,0),MATCH(S$5,$H$10:$L$10,0)) -> 2 | AG17: =INDEX($H$11:$L$19,MATCH($AA17,$G$11:$G$19,0),MATCH(T$5,$H$10:$L$10,0)) -> 2 | AH17: =INDEX($H$11:$L$19,MATCH("DD",$G$11:$G$19,0),MATCH(AH$5,$H$10:$L$10,0)) -> 8 | AI17: =L14 -> 7 | AJ17: =AL17*$X$43 -> 22400 | AK17: =PRODUCT(AE17:AI17) -> 224 | AL17: =IF(AD17>Q15,AD17,Q15)*(AK17/$X$43) -> 7.168e-05
A18: AA | B18: DD | C18: BB | D18: FF | E18: AA | G18: SC | H18: =COUNTIF(A$1:A$899,$G18) -> 2 | I18: =COUNTIF(B$1:B$899,$G18) -> 2 | J18: =COUNTIF(C$1:C$899,$G18) -> 2 | K18: =COUNTIF(D$1:D$899,$G18) -> 2 | L18: =COUNTIF(E$1:E$899,$G18) -> 2 | O18: EE | P18: 5 | Q18: ='Game Description'!E19 -> 100 | R18: =INDEX($H$11:$L$19,MATCH($O18,$G$11:$G$18,0),MATCH(R$5,$H$10:$L$10,0))+H$19 -> 8 | S18: =INDEX($H$11:$L$19,MATCH($O18,$G$11:$G$18,0),MATCH(S$5,$H$10:$L$10,0))+I$19 -> 9 | T18: =INDEX($H$11:$L$19,MATCH($O18,$G$11:$G$18,0),MATCH(T$5,$H$10:$L$10,0))+J$19 -> 8 | U18: =INDEX($H$11:$L$19,MATCH($O18,$G$11:$G$18,0),MATCH(U$5,$H$10:$L$10,0))+K$19 -> 10 | V18: =INDEX($H$11:$L$19,MATCH($O18,$G$11:$G$18,0),MATCH(V$5,$H$10:$L$10,0))+L$19 -> 10 | W18: =X18*Q18 -> 5726400 | X18: =PRODUCT(R18:V18)-AK18-AK20-AK27 -> 57264 | Y18: =(X18/$X$43)*Q18 -> 0.01832448 | Z18: =SUM(Y15:Y17) -> 0.05537792 | AA18: WD | AB18: EE | AC18: 4 | AD18: ='Game Description'!$D$22 -> 400 | AE18: =INDEX($H$11:$L$19,MATCH($AA18,$G$11:$G$19,0),MATCH(R$5,$H$10:$L$10,0)) -> 1 | AF18: =INDEX($H$11:$L$19,MATCH($AA18,$G$11:$G$19,0),MATCH(S$5,$H$10:$L$10,0)) -> 2 | AG18: =INDEX($H$11:$L$19,MATCH($AA18,$G$11:$G$19,0),MATCH(T$5,$H$10:$L$10,0)) -> 2 | AH18: =INDEX($H$11:$L$19,MATCH($AA18,$G$11:$G$19,0),MATCH(U$5,$H$10:$L$10,0)) -> 2 | AI18: =INDEX($H$11:$L$19,MATCH("EE",$G$11:$G$19,0),MATCH(AI$5,$H$10:$L$10,0)) -> 8 | AJ18: =AL18*$X$43 -> 25600 | AK18: =PRODUCT(AE18:AI18) -> 64 | AL18: =IF(AD18>Q18,AD18,Q18)*(AK18/$X$43) -> 8.192e-05
A19: FF | B19: AA | C19: GG | D19: SC | E19: GG | G19: WD | H19: =COUNTIF(A$1:A$899,$G19) -> 1 | I19: =COUNTIF(B$1:B$899,$G19) -> 2 | J19: =COUNTIF(C$1:C$899,$G19) -> 2 | K19: =COUNTIF(D$1:D$899,$G19) -> 2 | L19: =COUNTIF(E$1:E$899,$G19) -> 2 | O19: EE | P19: 4 | Q19: ='Game Description'!D19 -> 20 | R19: =INDEX($H$11:$L$19,MATCH($O19,$G$11:$G$18,0),MATCH(R$5,$H$10:$L$10,0))+H$19 -> 8 | S19: =INDEX($H$11:$L$19,MATCH($O19,$G$11:$G$18,0),MATCH(S$5,$H$10:$L$10,0))+I$19 -> 9 | T19: =INDEX($H$11:$L$19,MATCH($O19,$G$11:$G$18,0),MATCH(T$5,$H$10:$L$10,0))+J$19 -> 8 | U19: =INDEX($H$11:$L$19,MATCH($O19,$G$11:$G$18,0),MATCH(U$5,$H$10:$L$10,0))+K$19 -> 10 | V19: =L$20-(L$19+INDEX($H$11:$L$19,MATCH($O19,$G$11:$G$17,0),MATCH(V$5,$H$10:$L$10,0))) -> 40 | W19: =X19*Q19 -> 4576000 | X19: =PRODUCT(R19:V19)-PRODUCT($H$19:$K$19)*$V19-$AK19 -> 228800 | Y19: =(X19/$X$43)*Q19 -> 0.0146432 | AA19: WD | AB19: EE | AC19: 3 | AD19: ='Game Description'!$C$22 -> 40 | AE19: =INDEX($H$11:$L$19,MATCH($AA19,$G$11:$G$19,0),MATCH(R$5,$H$10:$L$10,0)) -> 1 | AF19: =INDEX($H$11:$L$19,MATCH($AA19,$G$11:$G$19,0),MATCH(S$5,$H$10:$L$10,0)) -> 2 | AG19: =INDEX($H$11:$L$19,MATCH($AA19,$G$11:$G$19,0),MATCH(T$5,$H$10:$L$10,0)) -> 2 | AH19: =INDEX($H$11:$L$19,MATCH("EE",$G$11:$G$19,0),MATCH(AH$5,$H$10:$L$10,0)) -> 8 | AI19: =$L$20-L$19-L15 -> 40 | AJ19: =AL19*$X$43 -> 51200 | AK19: =PRODUCT(AE19:AI19) -> 1280 | AL19: =IF(AD19>Q19,AD19,Q19)*(AK19/$X$43) -> 0.00016384
A20: SC | B20: SC | C20: EE | D20: DD | E20: AA | G20: Total | H20: =SUM(H11:H19) -> 50 | I20: =SUM(I11:I19) -> 50 | J20: =SUM(J11:J19) -> 50 | K20: =SUM(K11:K19) -> 50 | L20: =SUM(L11:L19) -> 50 | O20: EE | P20: 3 | Q20: ='Game Description'!C19 -> 5 | R20: =INDEX($H$11:$L$19,MATCH($O20,$G$11:$G$18,0),MATCH(R$5,$H$10:$L$10,0))+H$19 -> 8 | S20: =INDEX($H$11:$L$19,MATCH($O20,$G$11:$G$18,0),MATCH(S$5,$H$10:$L$10,0))+I$19 -> 9 | T20: =INDEX($H$11:$L$19,MATCH($O20,$G$11:$G$18,0),MATCH(T$5,$H$10:$L$10,0))+J$19 -> 8 | U20: =K$20-(K$19+INDEX($H$11:$L$19,MATCH($O20,$G$11:$G$18,0),MATCH(U$5,$H$10:$L$10,0))) -> 40 | V20: =$L$20 -> 50 | W20: =X20*Q20 -> 5720000 | X20: =PRODUCT(R20:V20)- PRODUCT($H$19:$J$19)*U20*V20 -> 1144000 | Y20: =(X20/$X$43)*Q20 -> 0.018304 | AA20: WD | AB20: EE | AC20: 3 | AD20: ='Game Description'!$C$22 -> 40 | AE20: =INDEX($H$11:$L$19,MATCH($AA20,$G$11:$G$19,0),MATCH(R$5,$H$10:$L$10,0)) -> 1 | AF20: =INDEX($H$11:$L$19,MATCH($AA20,$G$11:$G$19,0),MATCH(S$5,$H$10:$L$10,0)) -> 2 | AG20: =INDEX($H$11:$L$19,MATCH($AA20,$G$11:$G$19,0),MATCH(T$5,$H$10:$L$10,0)) -> 2 | AH20: =INDEX($H$11:$L$19,MATCH("EE",$G$11:$G$19,0),MATCH(AH$5,$H$10:$L$10,0)) -> 8 | AI20: =L15 -> 8 | AJ20: =AL20*$X$43 -> 25600 | AK20: =PRODUCT(AE20:AI20) -> 256 | AL20: =IF(AD20>Q18,AD20,Q18)*(AK20/$X$43) -> 8.192e-05
A21: FF | B21: EE | C21: FF | D21: DD | E21: GG | O21: FF | P21: 5 | Q21: ='Game Description'!E20 -> 50 | R21: =INDEX($H$11:$L$19,MATCH($O21,$G$11:$G$18,0),MATCH(R$5,$H$10:$L$10,0))+H$19 -> 11 | S21: =INDEX($H$11:$L$19,MATCH($O21,$G$11:$G$18,0),MATCH(S$5,$H$10:$L$10,0))+I$19 -> 10 | T21: =INDEX($H$11:$L$19,MATCH($O21,$G$11:$G$18,0),MATCH(T$5,$H$10:$L$10,0))+J$19 -> 12 | U21: =INDEX($H$11:$L$19,MATCH($O21,$G$11:$G$18,0),MATCH(U$5,$H$10:$L$10,0))+K$19 -> 12 | V21: =INDEX($H$11:$L$19,MATCH($O21,$G$11:$G$18,0),MATCH(V$5,$H$10:$L$10,0))+L$19 -> 12 | W21: =X21*Q21 -> 9479200 | X21: =PRODUCT(R21:V21)-AK21-AK23-AK27 -> 189584 | Y21: =(X21/$X$43)*Q21 -> 0.03033344 | Z21: =SUM(Y18:Y20) -> 0.05127168 | AA21: WD | AB21: FF | AC21: 4 | AD21: ='Game Description'!$D$22 -> 400 | AE21: =INDEX($H$11:$L$19,MATCH($AA21,$G$11:$G$19,0),MATCH(R$5,$H$10:$L$10,0)) -> 1 | AF21: =INDEX($H$11:$L$19,MATCH($AA21,$G$11:$G$19,0),MATCH(S$5,$H$10:$L$10,0)) -> 2 | AG21: =INDEX($H$11:$L$19,MATCH($AA21,$G$11:$G$19,0),MATCH(T$5,$H$10:$L$10,0)) -> 2 | AH21: =INDEX($H$11:$L$19,MATCH($AA21,$G$11:$G$19,0),MATCH(U$5,$H$10:$L$10,0)) -> 2 | AI21: =INDEX($H$11:$L$19,MATCH("FF",$G$11:$G$19,0),MATCH(AI$5,$H$10:$L$10,0)) -> 10 | AJ21: =AL21*$X$43 -> 32000 | AK21: =PRODUCT(AE21:AI21) -> 80 | AL21: =IF(AD21>Q21,AD21,Q21)*(AK21/$X$43) -> 0.0001024
A22: CC | B22: CC | C22: BB | D22: DD | E22: GG | O22: FF | P22: 4 | Q22: ='Game Description'!D20 -> 10 | R22: =INDEX($H$11:$L$19,MATCH($O22,$G$11:$G$18,0),MATCH(R$5,$H$10:$L$10,0))+H$19 -> 11 | S22: =INDEX($H$11:$L$19,MATCH($O22,$G$11:$G$18,0),MATCH(S$5,$H$10:$L$10,0))+I$19 -> 10 | T22: =INDEX($H$11:$L$19,MATCH($O22,$G$11:$G$18,0),MATCH(T$5,$H$10:$L$10,0))+J$19 -> 12 | U22: =INDEX($H$11:$L$19,MATCH($O22,$G$11:$G$18,0),MATCH(U$5,$H$10:$L$10,0))+K$19 -> 12 | V22: =L$20-(L$19+INDEX($H$11:$L$19,MATCH($O22,$G$11:$G$17,0),MATCH(V$5,$H$10:$L$10,0))) -> 38 | W22: =X22*Q22 -> 6000960 | X22: =PRODUCT(R22:V22)-PRODUCT($H$19:$K$19)*$V22-$AK22 -> 600096 | Y22: =(X22/$X$43)*Q22 -> 0.019203072 | AA22: WD | AB22: FF | AC22: 3 | AD22: ='Game Description'!$C$22 -> 40 | AE22: =INDEX($H$11:$L$19,MATCH($AA22,$G$11:$G$19,0),MATCH(R$5,$H$10:$L$10,0)) -> 1 | AF22: =INDEX($H$11:$L$19,MATCH($AA22,$G$11:$G$19,0),MATCH(S$5,$H$10:$L$10,0)) -> 2 | AG22: =INDEX($H$11:$L$19,MATCH($AA22,$G$11:$G$19,0),MATCH(T$5,$H$10:$L$10,0)) -> 2 | AH22: =INDEX($H$11:$L$19,MATCH("FF",$G$11:$G$19,0),MATCH(AH$5,$H$10:$L$10,0)) -> 10 | AI22: =$L$20-L$19-L16 -> 38 | AJ22: =AL22*$X$43 -> 60800 | AK22: =PRODUCT(AE22:AI22) -> 1520 | AL22: =IF(AD22>Q22,AD22,Q22)*(AK22/$X$43) -> 0.00019456
A23: AA | B23: GG | C23: SC | D23: AA | E23: SC | O23: FF | P23: 3 | Q23: ='Game Description'!C20 -> 1 | R23: =INDEX($H$11:$L$19,MATCH($O23,$G$11:$G$18,0),MATCH(R$5,$H$10:$L$10,0))+H$19 -> 11 | S23: =INDEX($H$11:$L$19,MATCH($O23,$G$11:$G$18,0),MATCH(S$5,$H$10:$L$10,0))+I$19 -> 10 | T23: =INDEX($H$11:$L$19,MATCH($O23,$G$11:$G$18,0),MATCH(T$5,$H$10:$L$10,0))+J$19 -> 12 | U23: =K$20-(K$19+INDEX($H$11:$L$19,MATCH($O23,$G$11:$G$18,0),MATCH(U$5,$H$10:$L$10,0))) -> 38 | V23: =$L$20 -> 50 | W23: =X23*Q23 -> 2500400 | X23: =PRODUCT(R23:V23)- PRODUCT($H$19:$J$19)*U23*V23 -> 2500400 | Y23: =(X23/$X$43)*Q23 -> 0.00800128 | AA23: WD | AB23: FF | AC23: 3 | AD23: ='Game Description'!$C$22 -> 40 | AE23: =INDEX($H$11:$L$19,MATCH($AA23,$G$11:$G$19,0),MATCH(R$5,$H$10:$L$10,0)) -> 1 | AF23: =INDEX($H$11:$L$19,MATCH($AA23,$G$11:$G$19,0),MATCH(S$5,$H$10:$L$10,0)) -> 2 | AG23: =INDEX($H$11:$L$19,MATCH($AA23,$G$11:$G$19,0),MATCH(T$5,$H$10:$L$10,0)) -> 2 | AH23: =INDEX($H$11:$L$19,MATCH("FF",$G$11:$G$19,0),MATCH(AH$5,$H$10:$L$10,0)) -> 10 | AI23: =L16 -> 10 | AJ23: =AL23*$X$43 -> 20000 | AK23: =PRODUCT(AE23:AI23) -> 400 | AL23: =IF(AD23>Q21,AD23,Q21)*(AK23/$X$43) -> 6.4e-05
A24: EE | B24: FF | C24: GG | D24: BB | E24: DD | O24: GG | P24: 5 | Q24: ='Game Description'!E21 -> 50 | R24: =INDEX($H$11:$L$19,MATCH($O24,$G$11:$G$18,0),MATCH(R$5,$H$10:$L$10,0))+H$19 -> 11 | S24: =INDEX($H$11:$L$19,MATCH($O24,$G$11:$G$18,0),MATCH(S$5,$H$10:$L$10,0))+I$19 -> 13 | T24: =INDEX($H$11:$L$19,MATCH($O24,$G$11:$G$18,0),MATCH(T$5,$H$10:$L$10,0))+J$19 -> 11 | U24: =INDEX($H$11:$L$19,MATCH($O24,$G$11:$G$18,0),MATCH(U$5,$H$10:$L$10,0))+K$19 -> 11 | V24: =INDEX($H$11:$L$19,MATCH($O24,$G$11:$G$18,0),MATCH(V$5,$H$10:$L$10,0))+L$19 -> 10 | W24: =X24*Q24 -> 8633100 | X24: =PRODUCT(R24:V24)-AK24-AK26-AK27 -> 172662 | Y24: =(X24/$X$43)*Q24 -> 0.02762592 | Z24: =SUM(Y21:Y23) -> 0.057537792 | AA24: WD | AB24: GG | AC24: 4 | AD24: ='Game Description'!$D$22 -> 400 | AE24: =INDEX($H$11:$L$19,MATCH($AA24,$G$11:$G$19,0),MATCH(R$5,$H$10:$L$10,0)) -> 1 | AF24: =INDEX($H$11:$L$19,MATCH($AA24,$G$11:$G$19,0),MATCH(S$5,$H$10:$L$10,0)) -> 2 | AG24: =INDEX($H$11:$L$19,MATCH($AA24,$G$11:$G$19,0),MATCH(T$5,$H$10:$L$10,0)) -> 2 | AH24: =INDEX($H$11:$L$19,MATCH($AA24,$G$11:$G$19,0),MATCH(U$5,$H$10:$L$10,0)) -> 2 | AI24: =INDEX($H$11:$L$19,MATCH("GG",$G$11:$G$19,0),MATCH(AI$5,$H$10:$L$10,0)) -> 8 | AJ24: =AL24*$X$43 -> 25600 | AK24: =PRODUCT(AE24:AI24) -> 64 | AL24: =IF(AD24>Q24,AD24,Q24)*(AK24/$X$43) -> 8.192e-05
A25: CC | B25: FF | C25: FF | D25: FF | E25: DD | O25: GG | P25: 4 | Q25: ='Game Description'!D21 -> 10 | R25: =INDEX($H$11:$L$19,MATCH($O25,$G$11:$G$18,0),MATCH(R$5,$H$10:$L$10,0))+H$19 -> 11 | S25: =INDEX($H$11:$L$19,MATCH($O25,$G$11:$G$18,0),MATCH(S$5,$H$10:$L$10,0))+I$19 -> 13 | T25: =INDEX($H$11:$L$19,MATCH($O25,$G$11:$G$18,0),MATCH(T$5,$H$10:$L$10,0))+J$19 -> 11 | U25: =INDEX($H$11:$L$19,MATCH($O25,$G$11:$G$18,0),MATCH(U$5,$H$10:$L$10,0))+K$19 -> 11 | V25: =L$20-(L$19+INDEX($H$11:$L$19,MATCH($O25,$G$11:$G$17,0),MATCH(V$5,$H$10:$L$10,0))) -> 40 | W25: =X25*Q25 -> 6903600 | X25: =PRODUCT(R25:V25)-PRODUCT($H$19:$K$19)*$V25-$AK25 -> 690360 | Y25: =(X25/$X$43)*Q25 -> 0.02209152 | AA25: WD | AB25: GG | AC25: 3 | AD25: ='Game Description'!$C$22 -> 40 | AE25: =INDEX($H$11:$L$19,MATCH($AA25,$G$11:$G$19,0),MATCH(R$5,$H$10:$L$10,0)) -> 1 | AF25: =INDEX($H$11:$L$19,MATCH($AA25,$G$11:$G$19,0),MATCH(S$5,$H$10:$L$10,0)) -> 2 | AG25: =INDEX($H$11:$L$19,MATCH($AA25,$G$11:$G$19,0),MATCH(T$5,$H$10:$L$10,0)) -> 2 | AH25: =INDEX($H$11:$L$19,MATCH("GG",$G$11:$G$19,0),MATCH(AH$5,$H$10:$L$10,0)) -> 9 | AI25: =L20-L19-L17 -> 40 | AJ25: =AL25*$X$43 -> 57600 | AK25: =PRODUCT(AE25:AI25) -> 1440 | AL25: =IF(AD25>Q25,AD25,Q25)*(AK25/$X$43) -> 0.00018432
A26: FF | B26: BB | C26: WD | D26: FF | E26: DD | O26: GG | P26: 3 | Q26: ='Game Description'!C21 -> 1 | R26: =INDEX($H$11:$L$19,MATCH($O26,$G$11:$G$18,0),MATCH(R$5,$H$10:$L$10,0))+H$19 -> 11 | S26: =INDEX($H$11:$L$19,MATCH($O26,$G$11:$G$18,0),MATCH(S$5,$H$10:$L$10,0))+I$19 -> 13 | T26: =INDEX($H$11:$L$19,MATCH($O26,$G$11:$G$18,0),MATCH(T$5,$H$10:$L$10,0))+J$19 -> 11 | U26: =K$20-(K$19+INDEX($H$11:$L$19,MATCH($O26,$G$11:$G$18,0),MATCH(U$5,$H$10:$L$10,0))) -> 39 | V26: =$L$20 -> 50 | W26: =X26*Q26 -> 3059550 | X26: =PRODUCT(R26:V26)- PRODUCT($H$19:$J$19)*U26*V26 -> 3059550 | Y26: =(X26/$X$43)*Q26 -> 0.00979056 | AA26: WD | AB26: GG | AC26: 3 | AD26: ='Game Description'!$C$22 -> 40 | AE26: =INDEX($H$11:$L$19,MATCH($AA26,$G$11:$G$19,0),MATCH(R$5,$H$10:$L$10,0)) -> 1 | AF26: =INDEX($H$11:$L$19,MATCH($AA26,$G$11:$G$19,0),MATCH(S$5,$H$10:$L$10,0)) -> 2 | AG26: =INDEX($H$11:$L$19,MATCH($AA26,$G$11:$G$19,0),MATCH(T$5,$H$10:$L$10,0)) -> 2 | AH26: =INDEX($H$11:$L$19,MATCH("GG",$G$11:$G$19,0),MATCH(AH$5,$H$10:$L$10,0)) -> 9 | AI26: =L17 -> 8 | AJ26: =AL26*$X$43 -> 14400 | AK26: =PRODUCT(AE26:AI26) -> 288 | AL26: =IF(AD26>Q24,AD26,Q24)*(AK26/$X$43) -> 4.608e-05
A27: FF | B27: CC | C27: FF | D27: FF | E27: FF | O27: SC | P27: 5 | Q27: ='Game Description'!E23 -> 500 | R27: =IF(G36=$O27,3*INDEX($H$11:$L$19,MATCH($O27,$G$11:$G$18,0),MATCH(R$5,$H$10:$L$10,0)),H$20-3*INDEX($H$11:$L$19,MATCH($O27,$G$11:$G$18,0),MATCH(R$5,$H$10:$L$10,0))) -> 6 | S27: =IF(H36=$O27,3*INDEX($H$11:$L$19,MATCH($O27,$G$11:$G$18,0),MATCH(S$5,$H$10:$L$10,0)),I$20-3*INDEX($H$11:$L$19,MATCH($O27,$G$11:$G$18,0),MATCH(S$5,$H$10:$L$10,0))) -> 6 | T27: =IF(I36=$O27,3*INDEX($H$11:$L$19,MATCH($O27,$G$11:$G$18,0),MATCH(T$5,$H$10:$L$10,0)),J$20-3*INDEX($H$11:$L$19,MATCH($O27,$G$11:$G$18,0),MATCH(T$5,$H$10:$L$10,0))) -> 6 | U27: =IF(J36=$O27,3*INDEX($H$11:$L$19,MATCH($O27,$G$11:$G$18,0),MATCH(U$5,$H$10:$L$10,0)),K$20-3*INDEX($H$11:$L$19,MATCH($O27,$G$11:$G$18,0),MATCH(U$5,$H$10:$L$10,0))) -> 6 | V27: =IF(K36=$O27,3*INDEX($H$11:$L$19,MATCH($O27,$G$11:$G$18,0),MATCH(V$5,$H$10:$L$10,0)),L$20-3*INDEX($H$11:$L$19,MATCH($O27,$G$11:$G$18,0),MATCH(V$5,$H$10:$L$10,0))) -> 6 | W27: =X27*Q27 -> 3888000 | X27: =PRODUCT(R27:V27) -> 7776 | Y27: =(X27/$X$43)*Q27 -> 0.0124416 | Z27: =SUM(Y24:Y26) -> 0.059508 | AE27: =H19 -> 1 | AF27: =I19 -> 2 | AG27: =J19 -> 2 | AH27: =K19 -> 2 | AI27: =L19 -> 2 | AJ27: =AL27*$X$43 -> 16000 | AK27: =PRODUCT(AE27:AI27) -> 16 | AL27: =AK27/X43*'Game Description'!E22 -> 5.12e-05
A28: GG | B28: GG | C28: FF | D28: WD | E28: FF | O28: SC | P28: 4 | Q28: ='Game Description'!$D$23 -> 50 | R28: =IF(G37=$O28,3*INDEX($H$11:$L$19,MATCH($O28,$G$11:$G$18,0),MATCH(R$5,$H$10:$L$10,0)),H$20-3*INDEX($H$11:$L$19,MATCH($O28,$G$11:$G$18,0),MATCH(R$5,$H$10:$L$10,0))) -> 6 | S28: =IF(H37=$O28,3*INDEX($H$11:$L$19,MATCH($O28,$G$11:$G$18,0),MATCH(S$5,$H$10:$L$10,0)),I$20-3*INDEX($H$11:$L$19,MATCH($O28,$G$11:$G$18,0),MATCH(S$5,$H$10:$L$10,0))) -> 6 | T28: =IF(I37=$O28,3*INDEX($H$11:$L$19,MATCH($O28,$G$11:$G$18,0),MATCH(T$5,$H$10:$L$10,0)),J$20-3*INDEX($H$11:$L$19,MATCH($O28,$G$11:$G$18,0),MATCH(T$5,$H$10:$L$10,0))) -> 6 | U28: =IF(J37=$O28,3*INDEX($H$11:$L$19,MATCH($O28,$G$11:$G$18,0),MATCH(U$5,$H$10:$L$10,0)),K$20-3*INDEX($H$11:$L$19,MATCH($O28,$G$11:$G$18,0),MATCH(U$5,$H$10:$L$10,0))) -> 6 | V28: =IF(K37=$O28,3*INDEX($H$11:$L$19,MATCH($O28,$G$11:$G$18,0),MATCH(V$5,$H$10:$L$10,0)),L$20-3*INDEX($H$11:$L$19,MATCH($O28,$G$11:$G$18,0),MATCH(V$5,$H$10:$L$10,0))) -> 44 | W28: =X28*Q28 -> 2851200 | X28: =PRODUCT(R28:V28) -> 57024 | Y28: =(X28/$X$43)*Q28 -> 0.00912384 | Z28: =SUM(Z9:Z27) -> 0.38307907 | AJ28: =AL28*$X$43 -> 6400 | AK28: =PRODUCT($H$19:$K$19)*L18 -> 16 | AL28: =(AK28/$X$43)*'Game Description'!$D$22 -> 2.048e-05
A29: FF | B29: GG | C29: FF | D29: AA | E29: FF | O29: SC | P29: 4 | Q29: ='Game Description'!$D$23 -> 50 | R29: =IF(G38=$O29,3*INDEX($H$11:$L$19,MATCH($O29,$G$11:$G$18,0),MATCH(R$5,$H$10:$L$10,0)),H$20-3*INDEX($H$11:$L$19,MATCH($O29,$G$11:$G$18,0),MATCH(R$5,$H$10:$L$10,0))) -> 6 | S29: =IF(H38=$O29,3*INDEX($H$11:$L$19,MATCH($O29,$G$11:$G$18,0),MATCH(S$5,$H$10:$L$10,0)),I$20-3*INDEX($H$11:$L$19,MATCH($O29,$G$11:$G$18,0),MATCH(S$5,$H$10:$L$10,0))) -> 6 | T29: =IF(I38=$O29,3*INDEX($H$11:$L$19,MATCH($O29,$G$11:$G$18,0),MATCH(T$5,$H$10:$L$10,0)),J$20-3*INDEX($H$11:$L$19,MATCH($O29,$G$11:$G$18,0),MATCH(T$5,$H$10:$L$10,0))) -> 6 | U29: =IF(J38=$O29,3*INDEX($H$11:$L$19,MATCH($O29,$G$11:$G$18,0),MATCH(U$5,$H$10:$L$10,0)),K$20-3*INDEX($H$11:$L$19,MATCH($O29,$G$11:$G$18,0),MATCH(U$5,$H$10:$L$10,0))) -> 44 | V29: =IF(K38=$O29,3*INDEX($H$11:$L$19,MATCH($O29,$G$11:$G$18,0),MATCH(V$5,$H$10:$L$10,0)),L$20-3*INDEX($H$11:$L$19,MATCH($O29,$G$11:$G$18,0),MATCH(V$5,$H$10:$L$10,0))) -> 6 | W29: =X29*Q29 -> 2851200 | X29: =PRODUCT(R29:V29) -> 57024 | Y29: =(X29/$X$43)*Q29 -> 0.00912384 | AJ29: =AL29*$X$43 -> 16000 | AK29: =PRODUCT($H$19:$J$19)*K18*$L$20 -> 400 | AL29: =(AK29/$X$43)*'Game Description'!$C$22 -> 5.12e-05
A30: DD | B30: GG | C30: EE | D30: FF | E30: GG | O30: SC | P30: 4 | Q30: ='Game Description'!$D$23 -> 50 | R30: =IF(G39=$O30,3*INDEX($H$11:$L$19,MATCH($O30,$G$11:$G$18,0),MATCH(R$5,$H$10:$L$10,0)),H$20-3*INDEX($H$11:$L$19,MATCH($O30,$G$11:$G$18,0),MATCH(R$5,$H$10:$L$10,0))) -> 6 | S30: =IF(H39=$O30,3*INDEX($H$11:$L$19,MATCH($O30,$G$11:$G$18,0),MATCH(S$5,$H$10:$L$10,0)),I$20-3*INDEX($H$11:$L$19,MATCH($O30,$G$11:$G$18,0),MATCH(S$5,$H$10:$L$10,0))) -> 6 | T30: =IF(I39=$O30,3*INDEX($H$11:$L$19,MATCH($O30,$G$11:$G$18,0),MATCH(T$5,$H$10:$L$10,0)),J$20-3*INDEX($H$11:$L$19,MATCH($O30,$G$11:$G$18,0),MATCH(T$5,$H$10:$L$10,0))) -> 44 | U30: =IF(J39=$O30,3*INDEX($H$11:$L$19,MATCH($O30,$G$11:$G$18,0),MATCH(U$5,$H$10:$L$10,0)),K$20-3*INDEX($H$11:$L$19,MATCH($O30,$G$11:$G$18,0),MATCH(U$5,$H$10:$L$10,0))) -> 6 | V30: =IF(K39=$O30,3*INDEX($H$11:$L$19,MATCH($O30,$G$11:$G$18,0),MATCH(V$5,$H$10:$L$10,0)),L$20-3*INDEX($H$11:$L$19,MATCH($O30,$G$11:$G$18,0),MATCH(V$5,$H$10:$L$10,0))) -> 6 | W30: =X30*Q30 -> 2851200 | X30: =PRODUCT(R30:V30) -> 57024 | Y30: =(X30/$X$43)*Q30 -> 0.00912384 | AJ30: =SUM(AJ6:AJ29) -> 720480 | AK30: =SUM(AK6:AK27) -> 9216 | AL30: =SUM(AL6:AL29) -> 0.002305536
A31: GG | B31: DD | C31: AA | D31: EE | E31: FF | O31: SC | P31: 4 | Q31: ='Game Description'!$D$23 -> 50 | R31: =IF(G40=$O31,3*INDEX($H$11:$L$19,MATCH($O31,$G$11:$G$18,0),MATCH(R$5,$H$10:$L$10,0)),H$20-3*INDEX($H$11:$L$19,MATCH($O31,$G$11:$G$18,0),MATCH(R$5,$H$10:$L$10,0))) -> 6 | S31: =IF(H40=$O31,3*INDEX($H$11:$L$19,MATCH($O31,$G$11:$G$18,0),MATCH(S$5,$H$10:$L$10,0)),I$20-3*INDEX($H$11:$L$19,MATCH($O31,$G$11:$G$18,0),MATCH(S$5,$H$10:$L$10,0))) -> 44 | T31: =IF(I40=$O31,3*INDEX($H$11:$L$19,MATCH($O31,$G$11:$G$18,0),MATCH(T$5,$H$10:$L$10,0)),J$20-3*INDEX($H$11:$L$19,MATCH($O31,$G$11:$G$18,0),MATCH(T$5,$H$10:$L$10,0))) -> 6 | U31: =IF(J40=$O31,3*INDEX($H$11:$L$19,MATCH($O31,$G$11:$G$18,0),MATCH(U$5,$H$10:$L$10,0)),K$20-3*INDEX($H$11:$L$19,MATCH($O31,$G$11:$G$18,0),MATCH(U$5,$H$10:$L$10,0))) -> 6 | V31: =IF(K40=$O31,3*INDEX($H$11:$L$19,MATCH($O31,$G$11:$G$18,0),MATCH(V$5,$H$10:$L$10,0)),L$20-3*INDEX($H$11:$L$19,MATCH($O31,$G$11:$G$18,0),MATCH(V$5,$H$10:$L$10,0))) -> 6 | W31: =X31*Q31 -> 2851200 | X31: =PRODUCT(R31:V31) -> 57024 | Y31: =(X31/$X$43)*Q31 -> 0.00912384
A32: DD | B32: CC | C32: EE | D32: DD | E32: WD | O32: SC | P32: 4 | Q32: ='Game Description'!$D$23 -> 50 | R32: =IF(G41=$O32,3*INDEX($H$11:$L$19,MATCH($O32,$G$11:$G$18,0),MATCH(R$5,$H$10:$L$10,0)),H$20-3*INDEX($H$11:$L$19,MATCH($O32,$G$11:$G$18,0),MATCH(R$5,$H$10:$L$10,0))) -> 44 | S32: =IF(H41=$O32,3*INDEX($H$11:$L$19,MATCH($O32,$G$11:$G$18,0),MATCH(S$5,$H$10:$L$10,0)),I$20-3*INDEX($H$11:$L$19,MATCH($O32,$G$11:$G$18,0),MATCH(S$5,$H$10:$L$10,0))) -> 6 | T32: =IF(I41=$O32,3*INDEX($H$11:$L$19,MATCH($O32,$G$11:$G$18,0),MATCH(T$5,$H$10:$L$10,0)),J$20-3*INDEX($H$11:$L$19,MATCH($O32,$G$11:$G$18,0),MATCH(T$5,$H$10:$L$10,0))) -> 6 | U32: =IF(J41=$O32,3*INDEX($H$11:$L$19,MATCH($O32,$G$11:$G$18,0),MATCH(U$5,$H$10:$L$10,0)),K$20-3*INDEX($H$11:$L$19,MATCH($O32,$G$11:$G$18,0),MATCH(U$5,$H$10:$L$10,0))) -> 6 | V32: =IF(K41=$O32,3*INDEX($H$11:$L$19,MATCH($O32,$G$11:$G$18,0),MATCH(V$5,$H$10:$L$10,0)),L$20-3*INDEX($H$11:$L$19,MATCH($O32,$G$11:$G$18,0),MATCH(V$5,$H$10:$L$10,0))) -> 6 | W32: =X32*Q32 -> 2851200 | X32: =PRODUCT(R32:V32) -> 57024 | Y32: =(X32/$X$43)*Q32 -> 0.00912384
A33: CC | B33: EE | C33: DD | D33: FF | E33: GG | O33: SC | P33: 3 | Q33: ='Game Description'!$C$23 -> 10 | R33: =IF(G42=$O33,3*INDEX($H$11:$L$19,MATCH($O33,$G$11:$G$18,0),MATCH(R$5,$H$10:$L$10,0)),H$20-3*INDEX($H$11:$L$19,MATCH($O33,$G$11:$G$18,0),MATCH(R$5,$H$10:$L$10,0))) -> 44 | S33: =IF(H42=$O33,3*INDEX($H$11:$L$19,MATCH($O33,$G$11:$G$18,0),MATCH(S$5,$H$10:$L$10,0)),I$20-3*INDEX($H$11:$L$19,MATCH($O33,$G$11:$G$18,0),MATCH(S$5,$H$10:$L$10,0))) -> 6 | T33: =IF(I42=$O33,3*INDEX($H$11:$L$19,MATCH($O33,$G$11:$G$18,0),MATCH(T$5,$H$10:$L$10,0)),J$20-3*INDEX($H$11:$L$19,MATCH($O33,$G$11:$G$18,0),MATCH(T$5,$H$10:$L$10,0))) -> 6 | U33: =IF(J42=$O33,3*INDEX($H$11:$L$19,MATCH($O33,$G$11:$G$18,0),MATCH(U$5,$H$10:$L$10,0)),K$20-3*INDEX($H$11:$L$19,MATCH($O33,$G$11:$G$18,0),MATCH(U$5,$H$10:$L$10,0))) -> 6 | V33: =IF(K42=$O33,3*INDEX($H$11:$L$19,MATCH($O33,$G$11:$G$18,0),MATCH(V$5,$H$10:$L$10,0)),L$20-3*INDEX($H$11:$L$19,MATCH($O33,$G$11:$G$18,0),MATCH(V$5,$H$10:$L$10,0))) -> 44 | W33: =X33*Q33 -> 4181760 | X33: =PRODUCT(R33:V33) -> 418176 | Y33: =(X33/$X$43)*Q33 -> 0.013381632
A34: EE | B34: FF | C34: DD | D34: GG | E34: EE | O34: SC | P34: 3 | Q34: ='Game Description'!$C$23 -> 10 | R34: =IF(G43=$O34,3*INDEX($H$11:$L$19,MATCH($O34,$G$11:$G$18,0),MATCH(R$5,$H$10:$L$10,0)),H$20-3*INDEX($H$11:$L$19,MATCH($O34,$G$11:$G$18,0),MATCH(R$5,$H$10:$L$10,0))) -> 6 | S34: =IF(H43=$O34,3*INDEX($H$11:$L$19,MATCH($O34,$G$11:$G$18,0),MATCH(S$5,$H$10:$L$10,0)),I$20-3*INDEX($H$11:$L$19,MATCH($O34,$G$11:$G$18,0),MATCH(S$5,$H$10:$L$10,0))) -> 44 | T34: =IF(I43=$O34,3*INDEX($H$11:$L$19,MATCH($O34,$G$11:$G$18,0),MATCH(T$5,$H$10:$L$10,0)),J$20-3*INDEX($H$11:$L$19,MATCH($O34,$G$11:$G$18,0),MATCH(T$5,$H$10:$L$10,0))) -> 6 | U34: =IF(J43=$O34,3*INDEX($H$11:$L$19,MATCH($O34,$G$11:$G$18,0),MATCH(U$5,$H$10:$L$10,0)),K$20-3*INDEX($H$11:$L$19,MATCH($O34,$G$11:$G$18,0),MATCH(U$5,$H$10:$L$10,0))) -> 6 | V34: =IF(K43=$O34,3*INDEX($H$11:$L$19,MATCH($O34,$G$11:$G$18,0),MATCH(V$5,$H$10:$L$10,0)),L$20-3*INDEX($H$11:$L$19,MATCH($O34,$G$11:$G$18,0),MATCH(V$5,$H$10:$L$10,0))) -> 44 | W34: =X34*Q34 -> 4181760 | X34: =PRODUCT(R34:V34) -> 418176 | Y34: =(X34/$X$43)*Q34 -> 0.013381632
A35: DD | B35: EE | C35: DD | D35: AA | E35: EE | G35: SC Combination | O35: SC | P35: 3 | Q35: ='Game Description'!$C$23 -> 10 | R35: =IF(G44=$O35,3*INDEX($H$11:$L$19,MATCH($O35,$G$11:$G$18,0),MATCH(R$5,$H$10:$L$10,0)),H$20-3*INDEX($H$11:$L$19,MATCH($O35,$G$11:$G$18,0),MATCH(R$5,$H$10:$L$10,0))) -> 44 | S35: =IF(H44=$O35,3*INDEX($H$11:$L$19,MATCH($O35,$G$11:$G$18,0),MATCH(S$5,$H$10:$L$10,0)),I$20-3*INDEX($H$11:$L$19,MATCH($O35,$G$11:$G$18,0),MATCH(S$5,$H$10:$L$10,0))) -> 6 | T35: =IF(I44=$O35,3*INDEX($H$11:$L$19,MATCH($O35,$G$11:$G$18,0),MATCH(T$5,$H$10:$L$10,0)),J$20-3*INDEX($H$11:$L$19,MATCH($O35,$G$11:$G$18,0),MATCH(T$5,$H$10:$L$10,0))) -> 44 | U35: =IF(J44=$O35,3*INDEX($H$11:$L$19,MATCH($O35,$G$11:$G$18,0),MATCH(U$5,$H$10:$L$10,0)),K$20-3*INDEX($H$11:$L$19,MATCH($O35,$G$11:$G$18,0),MATCH(U$5,$H$10:$L$10,0))) -> 6 | V35: =IF(K44=$O35,3*INDEX($H$11:$L$19,MATCH($O35,$G$11:$G$18,0),MATCH(V$5,$H$10:$L$10,0)),L$20-3*INDEX($H$11:$L$19,MATCH($O35,$G$11:$G$18,0),MATCH(V$5,$H$10:$L$10,0))) -> 6 | W35: =X35*Q35 -> 4181760 | X35: =PRODUCT(R35:V35) -> 418176 | Y35: =(X35/$X$43)*Q35 -> 0.013381632
A36: EE | B36: GG | C36: GG | D36: EE | E36: GG | G36: SC | H36: SC | I36: SC | J36: SC | K36: SC | O36: SC | P36: 3 | Q36: ='Game Description'!$C$23 -> 10 | R36: =IF(G45=$O36,3*INDEX($H$11:$L$19,MATCH($O36,$G$11:$G$18,0),MATCH(R$5,$H$10:$L$10,0)),H$20-3*INDEX($H$11:$L$19,MATCH($O36,$G$11:$G$18,0),MATCH(R$5,$H$10:$L$10,0))) -> 6 | S36: =IF(H45=$O36,3*INDEX($H$11:$L$19,MATCH($O36,$G$11:$G$18,0),MATCH(S$5,$H$10:$L$10,0)),I$20-3*INDEX($H$11:$L$19,MATCH($O36,$G$11:$G$18,0),MATCH(S$5,$H$10:$L$10,0))) -> 44 | T36: =IF(I45=$O36,3*INDEX($H$11:$L$19,MATCH($O36,$G$11:$G$18,0),MATCH(T$5,$H$10:$L$10,0)),J$20-3*INDEX($H$11:$L$19,MATCH($O36,$G$11:$G$18,0),MATCH(T$5,$H$10:$L$10,0))) -> 6 | U36: =IF(J45=$O36,3*INDEX($H$11:$L$19,MATCH($O36,$G$11:$G$18,0),MATCH(U$5,$H$10:$L$10,0)),K$20-3*INDEX($H$11:$L$19,MATCH($O36,$G$11:$G$18,0),MATCH(U$5,$H$10:$L$10,0))) -> 44 | V36: =IF(K45=$O36,3*INDEX($H$11:$L$19,MATCH($O36,$G$11:$G$18,0),MATCH(V$5,$H$10:$L$10,0)),L$20-3*INDEX($H$11:$L$19,MATCH($O36,$G$11:$G$18,0),MATCH(V$5,$H$10:$L$10,0))) -> 6 | W36: =X36*Q36 -> 4181760 | X36: =PRODUCT(R36:V36) -> 418176 | Y36: =(X36/$X$43)*Q36 -> 0.013381632
A37: GG | B37: WD | C37: GG | D37: FF | E37: EE | G37: SC | H37: SC | I37: SC | J37: SC | K37: -- | O37: SC | P37: 3 | Q37: ='Game Description'!$C$23 -> 10 | R37: =IF(G46=$O37,3*INDEX($H$11:$L$19,MATCH($O37,$G$11:$G$18,0),MATCH(R$5,$H$10:$L$10,0)),H$20-3*INDEX($H$11:$L$19,MATCH($O37,$G$11:$G$18,0),MATCH(R$5,$H$10:$L$10,0))) -> 6 | S37: =IF(H46=$O37,3*INDEX($H$11:$L$19,MATCH($O37,$G$11:$G$18,0),MATCH(S$5,$H$10:$L$10,0)),I$20-3*INDEX($H$11:$L$19,MATCH($O37,$G$11:$G$18,0),MATCH(S$5,$H$10:$L$10,0))) -> 6 | T37: =IF(I46=$O37,3*INDEX($H$11:$L$19,MATCH($O37,$G$11:$G$18,0),MATCH(T$5,$H$10:$L$10,0)),J$20-3*INDEX($H$11:$L$19,MATCH($O37,$G$11:$G$18,0),MATCH(T$5,$H$10:$L$10,0))) -> 44 | U37: =IF(J46=$O37,3*INDEX($H$11:$L$19,MATCH($O37,$G$11:$G$18,0),MATCH(U$5,$H$10:$L$10,0)),K$20-3*INDEX($H$11:$L$19,MATCH($O37,$G$11:$G$18,0),MATCH(U$5,$H$10:$L$10,0))) -> 6 | V37: =IF(K46=$O37,3*INDEX($H$11:$L$19,MATCH($O37,$G$11:$G$18,0),MATCH(V$5,$H$10:$L$10,0)),L$20-3*INDEX($H$11:$L$19,MATCH($O37,$G$11:$G$18,0),MATCH(V$5,$H$10:$L$10,0))) -> 44 | W37: =X37*Q37 -> 4181760 | X37: =PRODUCT(R37:V37) -> 418176 | Y37: =(X37/$X$43)*Q37 -> 0.013381632
A38: DD | B38: GG | C38: FF | D38: DD | E38: FF | G38: SC | H38: SC | I38: SC | J38: -- | K38: SC | O38: SC | P38: 3 | Q38: ='Game Description'!$C$23 -> 10 | R38: =IF(G47=$O38,3*INDEX($H$11:$L$19,MATCH($O38,$G$11:$G$18,0),MATCH(R$5,$H$10:$L$10,0)),H$20-3*INDEX($H$11:$L$19,MATCH($O38,$G$11:$G$18,0),MATCH(R$5,$H$10:$L$10,0))) -> 44 | S38: =IF(H47=$O38,3*INDEX($H$11:$L$19,MATCH($O38,$G$11:$G$18,0),MATCH(S$5,$H$10:$L$10,0)),I$20-3*INDEX($H$11:$L$19,MATCH($O38,$G$11:$G$18,0),MATCH(S$5,$H$10:$L$10,0))) -> 6 | T38: =IF(I47=$O38,3*INDEX($H$11:$L$19,MATCH($O38,$G$11:$G$18,0),MATCH(T$5,$H$10:$L$10,0)),J$20-3*INDEX($H$11:$L$19,MATCH($O38,$G$11:$G$18,0),MATCH(T$5,$H$10:$L$10,0))) -> 6 | U38: =IF(J47=$O38,3*INDEX($H$11:$L$19,MATCH($O38,$G$11:$G$18,0),MATCH(U$5,$H$10:$L$10,0)),K$20-3*INDEX($H$11:$L$19,MATCH($O38,$G$11:$G$18,0),MATCH(U$5,$H$10:$L$10,0))) -> 44 | V38: =IF(K47=$O38,3*INDEX($H$11:$L$19,MATCH($O38,$G$11:$G$18,0),MATCH(V$5,$H$10:$L$10,0)),L$20-3*INDEX($H$11:$L$19,MATCH($O38,$G$11:$G$18,0),MATCH(V$5,$H$10:$L$10,0))) -> 6 | W38: =X38*Q38 -> 4181760 | X38: =PRODUCT(R38:V38) -> 418176 | Y38: =(X38/$X$43)*Q38 -> 0.013381632
A39: GG | B39: GG | C39: GG | D39: BB | E39: FF | G39: SC | H39: SC | I39: -- | J39: SC | K39: SC | O39: SC | P39: 3 | Q39: ='Game Description'!$C$23 -> 10 | R39: =IF(G48=$O39,3*INDEX($H$11:$L$19,MATCH($O39,$G$11:$G$18,0),MATCH(R$5,$H$10:$L$10,0)),H$20-3*INDEX($H$11:$L$19,MATCH($O39,$G$11:$G$18,0),MATCH(R$5,$H$10:$L$10,0))) -> 6 | S39: =IF(H48=$O39,3*INDEX($H$11:$L$19,MATCH($O39,$G$11:$G$18,0),MATCH(S$5,$H$10:$L$10,0)),I$20-3*INDEX($H$11:$L$19,MATCH($O39,$G$11:$G$18,0),MATCH(S$5,$H$10:$L$10,0))) -> 6 | T39: =IF(I48=$O39,3*INDEX($H$11:$L$19,MATCH($O39,$G$11:$G$18,0),MATCH(T$5,$H$10:$L$10,0)),J$20-3*INDEX($H$11:$L$19,MATCH($O39,$G$11:$G$18,0),MATCH(T$5,$H$10:$L$10,0))) -> 44 | U39: =IF(J48=$O39,3*INDEX($H$11:$L$19,MATCH($O39,$G$11:$G$18,0),MATCH(U$5,$H$10:$L$10,0)),K$20-3*INDEX($H$11:$L$19,MATCH($O39,$G$11:$G$18,0),MATCH(U$5,$H$10:$L$10,0))) -> 44 | V39: =IF(K48=$O39,3*INDEX($H$11:$L$19,MATCH($O39,$G$11:$G$18,0),MATCH(V$5,$H$10:$L$10,0)),L$20-3*INDEX($H$11:$L$19,MATCH($O39,$G$11:$G$18,0),MATCH(V$5,$H$10:$L$10,0))) -> 6 | W39: =X39*Q39 -> 4181760 | X39: =PRODUCT(R39:V39) -> 418176 | Y39: =(X39/$X$43)*Q39 -> 0.013381632
A40: WD | B40: FF | C40: GG | D40: DD | E40: CC | G40: SC | H40: -- | I40: SC | J40: SC | K40: SC | O40: SC | P40: 3 | Q40: ='Game Description'!$C$23 -> 10 | R40: =IF(G49=$O40,3*INDEX($H$11:$L$19,MATCH($O40,$G$11:$G$18,0),MATCH(R$5,$H$10:$L$10,0)),H$20-3*INDEX($H$11:$L$19,MATCH($O40,$G$11:$G$18,0),MATCH(R$5,$H$10:$L$10,0))) -> 6 | S40: =IF(H49=$O40,3*INDEX($H$11:$L$19,MATCH($O40,$G$11:$G$18,0),MATCH(S$5,$H$10:$L$10,0)),I$20-3*INDEX($H$11:$L$19,MATCH($O40,$G$11:$G$18,0),MATCH(S$5,$H$10:$L$10,0))) -> 44 | T40: =IF(I49=$O40,3*INDEX($H$11:$L$19,MATCH($O40,$G$11:$G$18,0),MATCH(T$5,$H$10:$L$10,0)),J$20-3*INDEX($H$11:$L$19,MATCH($O40,$G$11:$G$18,0),MATCH(T$5,$H$10:$L$10,0))) -> 44 | U40: =IF(J49=$O40,3*INDEX($H$11:$L$19,MATCH($O40,$G$11:$G$18,0),MATCH(U$5,$H$10:$L$10,0)),K$20-3*INDEX($H$11:$L$19,MATCH($O40,$G$11:$G$18,0),MATCH(U$5,$H$10:$L$10,0))) -> 6 | V40: =IF(K49=$O40,3*INDEX($H$11:$L$19,MATCH($O40,$G$11:$G$18,0),MATCH(V$5,$H$10:$L$10,0)),L$20-3*INDEX($H$11:$L$19,MATCH($O40,$G$11:$G$18,0),MATCH(V$5,$H$10:$L$10,0))) -> 6 | W40: =X40*Q40 -> 4181760 | X40: =PRODUCT(R40:V40) -> 418176 | Y40: =(X40/$X$43)*Q40 -> 0.013381632
...

Sheet FreeGameReel
B1: Basegame Reel Strip
A2: Reel 1 | B2: Reel 2 | C2: Reel 3 | D2: Reel 4 | E2: Reel 5
A3: GG | B3: EE | C3: FF | D3: DD | E3: EE | Q3: Base bet | R3: 20 | T3: retrigger spins | U3: 10
A4: GG | B4: EE | C4: FF | D4: GG | E4: EE
A5: GG | B5: EE | C5: FF | D5: EE | E5: EE | O5: Symbol | P5: Number | Q5: Payout | R5: Reel 1 | S5: Reel 2 | T5: Reel 3 | U5: Reel 4 | V5: Reel 5 | X5: Hits | Y5: RTP | AA5: Symbol | AB5: Symbols | AC5: Number | AD5: Payout | AE5: Reel 1 | AF5: Reel 2 | AG5: Reel 3 | AH5: Reel 4 | AI5: Reel 5 | AK5: Hits | AL5: RTP
A6: EE | B6: AA | C6: FF | D6: EE | E6: BB | O6: AA | P6: 5 | Q6: ='Game Description'!E15 -> 200 | R6: =INDEX($H$11:$L$19,MATCH($O6,$G$11:$G$18,0),MATCH(R$5,$H$10:$L$10,0))+H$19 -> 10 | S6: =INDEX($H$11:$L$19,MATCH($O6,$G$11:$G$18,0),MATCH(S$5,$H$10:$L$10,0))+I$19 -> 11 | T6: =INDEX($H$11:$L$19,MATCH($O6,$G$11:$G$18,0),MATCH(T$5,$H$10:$L$10,0))+J$19 -> 10 | U6: =INDEX($H$11:$L$19,MATCH($O6,$G$11:$G$18,0),MATCH(U$5,$H$10:$L$10,0))+K$19 -> 10 | V6: =INDEX($H$11:$L$19,MATCH($O6,$G$11:$G$18,0),MATCH(V$5,$H$10:$L$10,0))+L$19 -> 10 | W6: =X6*Q6 -> 17276800 | X6: =PRODUCT(R6:V6)-AK6-AK8-AK27 -> 86384 | Y6: =(X6/$X$43)*Q6 -> 0.05528576 | AA6: WD | AB6: AA | AC6: 4 | AD6: ='Game Description'!$D$22 -> 400 | AE6: =INDEX($H$11:$L$19,MATCH($AA6,$G$11:$G$19,0),MATCH(R$5,$H$10:$L$10,0)) -> 6 | AF6: =INDEX($H$11:$L$19,MATCH($AA6,$G$11:$G$19,0),MATCH(S$5,$H$10:$L$10,0)) -> 8 | AG6: =INDEX($H$11:$L$19,MATCH($AA6,$G$11:$G$19,0),MATCH(T$5,$H$10:$L$10,0)) -> 6 | AH6: =INDEX($H$11:$L$19,MATCH($AA6,$G$11:$G$19,0),MATCH(U$5,$H$10:$L$10,0)) -> 7 | AI6: =INDEX($H$11:$L$19,MATCH("AA",$G$11:$G$19,0),MATCH(AI$5,$H$10:$L$10,0)) -> 4 | AJ6: =AL6*$X$43 -> 3225600 | AK6: =PRODUCT(AE6:AI6) -> 8064 | AL6: =IF(AD6>Q6,AD6,Q6)*(AK6/$X$43) -> 0.01032192
A7: BB | B7: AA | C7: GG | D7: SC | E7: EE | O7: AA | P7: 4 | Q7: ='Game Description'!D15 -> 100 | R7: =INDEX($H$11:$L$19,MATCH($O7,$G$11:$G$18,0),MATCH(R$5,$H$10:$L$10,0))+H$19 -> 10 | S7: =INDEX($H$11:$L$19,MATCH($O7,$G$11:$G$18,0),MATCH(S$5,$H$10:$L$10,0))+I$19 -> 11 | T7: =INDEX($H$11:$L$19,MATCH($O7,$G$11:$G$18,0),MATCH(T$5,$H$10:$L$10,0))+J$19 -> 10 | U7: =INDEX($H$11:$L$19,MATCH($O7,$G$11:$G$18,0),MATCH(U$5,$H$10:$L$10,0))+K$19 -> 10 | V7: =L$20-(L$19+INDEX($H$11:$L$19,MATCH($O7,$G$11:$G$17,0),MATCH(V$5,$H$10:$L$10,0))) -> 40 | W7: =X7*Q7 -> 32480000 | X7: =PRODUCT(R7:V7)-PRODUCT($H$19:$K$19)*$V7-$AK7 -> 324800 | Y7: =(X7/$X$43)*Q7 -> 0.103936 | AA7: WD | AB7: AA | AC7: 3 | AD7: ='Game Description'!$C$22 -> 40 | AE7: =INDEX($H$11:$L$19,MATCH($AA7,$G$11:$G$19,0),MATCH(R$5,$H$10:$L$10,0)) -> 6 | AF7: =INDEX($H$11:$L$19,MATCH($AA7,$G$11:$G$19,0),MATCH(S$5,$H$10:$L$10,0)) -> 8 | AG7: =INDEX($H$11:$L$19,MATCH($AA7,$G$11:$G$19,0),MATCH(T$5,$H$10:$L$10,0)) -> 6 | AH7: =INDEX($H$11:$L$19,MATCH("AA",$G$11:$G$19,0),MATCH(AH$5,$H$10:$L$10,0)) -> 3 | AI7: =$L$20-L$19-L11 -> 40 | AJ7: =AL7*$X$43 -> 3456000 | AK7: =PRODUCT(AE7:AI7) -> 34560 | AL7: =IF(AD7>Q7,AD7,Q7)*(AK7/$X$43) -> 0.0110592
A8: WD | B8: GG | C8: SC | D8: BB | E8: CC | O8: AA | P8: 3 | Q8: ='Game Description'!C15 -> 20 | R8: =INDEX($H$11:$L$19,MATCH($O8,$G$11:$G$18,0),MATCH(R$5,$H$10:$L$10,0))+H$19 -> 10 | S8: =INDEX($H$11:$L$19,MATCH($O8,$G$11:$G$18,0),MATCH(S$5,$H$10:$L$10,0))+I$19 -> 11 | T8: =INDEX($H$11:$L$19,MATCH($O8,$G$11:$G$18,0),MATCH(T$5,$H$10:$L$10,0))+J$19 -> 10 | U8: =K$20-(K$19+INDEX($H$11:$L$19,MATCH($O8,$G$11:$G$18,0),MATCH(U$5,$H$10:$L$10,0))) -> 40 | V8: =$L$20 -> 50 | W8: =X8*Q8 -> 32480000 | X8: =PRODUCT(R8:V8)- PRODUCT($H$19:$J$19)*U8*V8 -> 1624000 | Y8: =(X8/$X$43)*Q8 -> 0.103936 | AA8: WD | AB8: AA | AC8: 3 | AD8: ='Game Description'!$C$22 -> 40 | AE8: =INDEX($H$11:$L$19,MATCH($AA8,$G$11:$G$19,0),MATCH(R$5,$H$10:$L$10,0)) -> 6 | AF8: =INDEX($H$11:$L$19,MATCH($AA8,$G$11:$G$19,0),MATCH(S$5,$H$10:$L$10,0)) -> 8 | AG8: =INDEX($H$11:$L$19,MATCH($AA8,$G$11:$G$19,0),MATCH(T$5,$H$10:$L$10,0)) -> 6 | AH8: =INDEX($H$11:$L$19,MATCH("AA",$G$11:$G$19,0),MATCH(AH$5,$H$10:$L$10,0)) -> 3 | AI8: =L11 -> 4 | AJ8: =AL8*$X$43 -> 691200 | AK8: =PRODUCT(AE8:AI8) -> 3456 | AL8: =IF(AD8>Q6,AD8,Q6)*(AK8/$X$43) -> 0.00221184
A9: WD | B9: CC | C9: BB | D9: EE | E9: FF | G9: With | O9: BB | P9: 5 | Q9: ='Game Description'!E16 -> 200 | R9: =INDEX($H$11:$L$19,MATCH($O9,$G$11:$G$18,0),MATCH(R$5,$H$10:$L$10,0))+H$19 -> 9 | S9: =INDEX($H$11:$L$19,MATCH($O9,$G$11:$G$18,0),MATCH(S$5,$H$10:$L$10,0))+I$19 -> 12 | T9: =INDEX($H$11:$L$19,MATCH($O9,$G$11:$G$18,0),MATCH(T$5,$H$10:$L$10,0))+J$19 -> 10 | U9: =INDEX($H$11:$L$19,MATCH($O9,$G$11:$G$18,0),MATCH(U$5,$H$10:$L$10,0))+K$19 -> 10 | V9: =INDEX($H$11:$L$19,MATCH($O9,$G$11:$G$18,0),MATCH(V$5,$H$10:$L$10,0))+L$19 -> 9 | W9: =X9*Q9 -> 15292800 | X9: =PRODUCT(R9:V9)-AK9-AK11-AK27 -> 76464 | Y9: =(X9/$X$43)*Q9 -> 0.04893696 | Z9: =SUM(Y6:Y8) -> 0.26315776 | AA9: WD | AB9: BB | AC9: 4 | AD9: ='Game Description'!$D$22 -> 400 | AE9: =INDEX($H$11:$L$19,MATCH($AA9,$G$11:$G$19,0),MATCH(R$5,$H$10:$L$10,0)) -> 6 | AF9: =INDEX($H$11:$L$19,MATCH($AA9,$G$11:$G$19,0),MATCH(S$5,$H$10:$L$10,0)) -> 8 | AG9: =INDEX($H$11:$L$19,MATCH($AA9,$G$11:$G$19,0),MATCH(T$5,$H$10:$L$10,0)) -> 6 | AH9: =INDEX($H$11:$L$19,MATCH($AA9,$G$11:$G$19,0),MATCH(U$5,$H$10:$L$10,0)) -> 7 | AI9: =INDEX($H$11:$L$19,MATCH("BB",$G$11:$G$19,0),MATCH(AI$5,$H$10:$L$10,0)) -> 3 | AJ9: =AL9*$X$43 -> 2419200 | AK9: =PRODUCT(AE9:AI9) -> 6048 | AL9: =IF(AD9>Q9,AD9,Q9)*(AK9/$X$43) -> 0.00774144
A10: AA | B10: EE | C10: BB | D10: EE | E10: EE | G10: Symbol | H10: Reel 1 | I10: Reel 2 | J10: Reel 3 | K10: Reel 4 | L10: Reel 5 | O10: BB | P10: 4 | Q10: ='Game Description'!D16 -> 100 | R10: =INDEX($H$11:$L$19,MATCH($O10,$G$11:$G$18,0),MATCH(R$5,$H$10:$L$10,0))+H$19 -> 9 | S10: =INDEX($H$11:$L$19,MATCH($O10,$G$11:$G$18,0),MATCH(S$5,$H$10:$L$10,0))+I$19 -> 12 | T10: =INDEX($H$11:$L$19,MATCH($O10,$G$11:$G$18,0),MATCH(T$5,$H$10:$L$10,0))+J$19 -> 10 | U10: =INDEX($H$11:$L$19,MATCH($O10,$G$11:$G$18,0),MATCH(U$5,$H$10:$L$10,0))+K$19 -> 10 | V10: =L$20-(L$19+INDEX($H$11:$L$19,MATCH($O10,$G$11:$G$17,0),MATCH(V$5,$H$10:$L$10,0))) -> 41 | W10: =X10*Q10 -> 32472000 | X10: =PRODUCT(R10:V10)-PRODUCT($H$19:$K$19)*$V10-$AK10 -> 324720 | Y10: =(X10/$X$43)*Q10 -> 0.1039104 | AA10: WD | AB10: BB | AC10: 3 | AD10: ='Game Description'!$C$22 -> 40 | AE10: =INDEX($H$11:$L$19,MATCH($AA10,$G$11:$G$19,0),MATCH(R$5,$H$10:$L$10,0)) -> 6 | AF10: =INDEX($H$11:$L$19,MATCH($AA10,$G$11:$G$19,0),MATCH(S$5,$H$10:$L$10,0)) -> 8 | AG10: =INDEX($H$11:$L$19,MATCH($AA10,$G$11:$G$19,0),MATCH(T$5,$H$10:$L$10,0)) -> 6 | AH10: =INDEX($H$11:$L$19,MATCH("BB",$G$11:$G$19,0),MATCH(AH$5,$H$10:$L$10,0)) -> 3 | AI10: =$L$20-L$19-L12 -> 41 | AJ10: =AL10*$X$43 -> 3542400 | AK10: =PRODUCT(AE10:AI10) -> 35424 | AL10: =IF(AD10>Q10,AD10,Q10)*(AK10/$X$43) -> 0.01133568
A11: AA | B11: SC | C11: BB | D11: GG | E11: SC | G11: AA | H11: =COUNTIF(A$1:A$899,$G11) -> 4 | I11: =COUNTIF(B$1:B$899,$G11) -> 3 | J11: =COUNTIF(C$1:C$899,$G11) -> 4 | K11: =COUNTIF(D$1:D$899,$G11) -> 3 | L11: =COUNTIF(E$1:E$899,$G11) -> 4 | O11: BB | P11: 3 | Q11: ='Game Description'!C16 -> 20 | R11: =INDEX($H$11:$L$19,MATCH($O11,$G$11:$G$18,0),MATCH(R$5,$H$10:$L$10,0))+H$19 -> 9 | S11: =INDEX($H$11:$L$19,MATCH($O11,$G$11:$G$18,0),MATCH(S$5,$H$10:$L$10,0))+I$19 -> 12 | T11: =INDEX($H$11:$L$19,MATCH($O11,$G$11:$G$18,0),MATCH(T$5,$H$10:$L$10,0))+J$19 -> 10 | U11: =K$20-(K$19+INDEX($H$11:$L$19,MATCH($O11,$G$11:$G$18,0),MATCH(U$5,$H$10:$L$10,0))) -> 40 | V11: =$L$20 -> 50 | W11: =X11*Q11 -> 31680000 | X11: =PRODUCT(R11:V11)- PRODUCT($H$19:$J$19)*U11*V11 -> 1584000 | Y11: =X11/$X$43*Q11 -> 0.101376 | AA11: WD | AB11: BB | AC11: 3 | AD11: ='Game Description'!$C$22 -> 40 | AE11: =INDEX($H$11:$L$19,MATCH($AA11,$G$11:$G$19,0),MATCH(R$5,$H$10:$L$10,0)) -> 6 | AF11: =INDEX($H$11:$L$19,MATCH($AA11,$G$11:$G$19,0),MATCH(S$5,$H$10:$L$10,0)) -> 8 | AG11: =INDEX($H$11:$L$19,MATCH($AA11,$G$11:$G$19,0),MATCH(T$5,$H$10:$L$10,0)) -> 6 | AH11: =INDEX($H$11:$L$19,MATCH("BB",$G$11:$G$19,0),MATCH(AH$5,$H$10:$L$10,0)) -> 3 | AI11: =L12 -> 3 | AJ11: =AL11*$X$43 -> 518400 | AK11: =PRODUCT(AE11:AI11) -> 2592 | AL11: =IF(AD11>Q9,AD11,Q9)*(AK11/$X$43) -> 0.00165888
A12: AA | B12: AA | C12: GG | D12: CC | E12: GG | G12: BB | H12: =COUNTIF(A$1:A$899,$G12) -> 3 | I12: =COUNTIF(B$1:B$899,$G12) -> 4 | J12: =COUNTIF(C$1:C$899,$G12) -> 4 | K12: =COUNTIF(D$1:D$899,$G12) -> 3 | L12: =COUNTIF(E$1:E$899,$G12) -> 3 | O12: CC | P12: 5 | Q12: ='Game Description'!E17 -> 200 | R12: =INDEX($H$11:$L$19,MATCH($O12,$G$11:$G$18,0),MATCH(R$5,$H$10:$L$10,0))+H$19 -> 10 | S12: =INDEX($H$11:$L$19,MATCH($O12,$G$11:$G$18,0),MATCH(S$5,$H$10:$L$10,0))+I$19 -> 10 | T12: =INDEX($H$11:$L$19,MATCH($O12,$G$11:$G$18,0),MATCH(T$5,$H$10:$L$10,0))+J$19 -> 10 | U12: =INDEX($H$11:$L$19,MATCH($O12,$G$11:$G$18,0),MATCH(U$5,$H$10:$L$10,0))+K$19 -> 11 | V12: =INDEX($H$11:$L$19,MATCH($O12,$G$11:$G$18,0),MATCH(V$5,$H$10:$L$10,0))+L$19 -> 10 | W12: =X12*Q12 -> 17046400 | X12: =PRODUCT(R12:V12)-AK12-AK14-AK27 -> 85232 | Y12: =(X12/$X$43)*Q12 -> 0.05454848 | Z12: =SUM(Y9:Y11) -> 0.25422336 | AA12: WD | AB12: CC | AC12: 4 | AD12: ='Game Description'!$D$22 -> 400 | AE12: =INDEX($H$11:$L$19,MATCH($AA12,$G$11:$G$19,0),MATCH(R$5,$H$10:$L$10,0)) -> 6 | AF12: =INDEX($H$11:$L$19,MATCH($AA12,$G$11:$G$19,0),MATCH(S$5,$H$10:$L$10,0)) -> 8 | AG12: =INDEX($H$11:$L$19,MATCH($AA12,$G$11:$G$19,0),MATCH(T$5,$H$10:$L$10,0)) -> 6 | AH12: =INDEX($H$11:$L$19,MATCH($AA12,$G$11:$G$19,0),MATCH(U$5,$H$10:$L$10,0)) -> 7 | AI12: =INDEX($H$11:$L$19,MATCH("CC",$G$11:$G$19,0),MATCH(AI$5,$H$10:$L$10,0)) -> 4 | AJ12: =AL12*$X$43 -> 3225600 | AK12: =PRODUCT(AE12:AI12) -> 8064 | AL12: =IF(AD12>Q12,AD12,Q12)*(AK12/$X$43) -> 0.01032192
A13: WD | B13: FF | C13: AA | D13: WD | E13: DD | G13: CC | H13: =COUNTIF(A$1:A$899,$G13) -> 4 | I13: =COUNTIF(B$1:B$899,$G13) -> 2 | J13: =COUNTIF(C$1:C$899,$G13) -> 4 | K13: =COUNTIF(D$1:D$899,$G13) -> 4 | L13: =COUNTIF(E$1:E$899,$G13) -> 4 | O13: CC | P13: 4 | Q13: ='Game Description'!D17 -> 100 | R13: =INDEX($H$11:$L$19,MATCH($O13,$G$11:$G$18,0),MATCH(R$5,$H$10:$L$10,0))+H$19 -> 10 | S13: =INDEX($H$11:$L$19,MATCH($O13,$G$11:$G$18,0),MATCH(S$5,$H$10:$L$10,0))+I$19 -> 10 | T13: =INDEX($H$11:$L$19,MATCH($O13,$G$11:$G$18,0),MATCH(T$5,$H$10:$L$10,0))+J$19 -> 10 | U13: =INDEX($H$11:$L$19,MATCH($O13,$G$11:$G$18,0),MATCH(U$5,$H$10:$L$10,0))+K$19 -> 11 | V13: =L$20-(L$19+INDEX($H$11:$L$19,MATCH($O13,$G$11:$G$17,0),MATCH(V$5,$H$10:$L$10,0))) -> 40 | W13: =X13*Q13 -> 31328000 | X13: =PRODUCT(R13:V13)-PRODUCT($H$19:$K$19)*$V13-$AK13 -> 313280 | Y13: =(X13/$X$43)*Q13 -> 0.1002496 | AA13: WD | AB13: CC | AC13: 3 | AD13: ='Game Description'!$C$22 -> 40 | AE13: =INDEX($H$11:$L$19,MATCH($AA13,$G$11:$G$19,0),MATCH(R$5,$H$10:$L$10,0)) -> 6 | AF13: =INDEX($H$11:$L$19,MATCH($AA13,$G$11:$G$19,0),MATCH(S$5,$H$10:$L$10,0)) -> 8 | AG13: =INDEX($H$11:$L$19,MATCH($AA13,$G$11:$G$19,0),MATCH(T$5,$H$10:$L$10,0)) -> 6 | AH13: =INDEX($H$11:$L$19,MATCH("CC",$G$11:$G$19,0),MATCH(AH$5,$H$10:$L$10,0)) -> 4 | AI13: =$L$20-L$19-L13 -> 40 | AJ13: =AL13*$X$43 -> 4608000 | AK13: =PRODUCT(AE13:AI13) -> 46080 | AL13: =IF(AD13>Q13,AD13,Q13)*(AK13/$X$43) -> 0.0147456
A14: GG | B14: WD | C14: AA | D14: GG | E14: WD | G14: DD | H14: =COUNTIF(A$1:A$899,$G14) -> 6 | I14: =COUNTIF(B$1:B$899,$G14) -> 5 | J14: =COUNTIF(C$1:C$899,$G14) -> 7 | K14: =COUNTIF(D$1:D$899,$G14) -> 7 | L14: =COUNTIF(E$1:E$899,$G14) -> 6 | O14: CC | P14: 3 | Q14: ='Game Description'!C17 -> 20 | R14: =INDEX($H$11:$L$19,MATCH($O14,$G$11:$G$18,0),MATCH(R$5,$H$10:$L$10,0))+H$19 -> 10 | S14: =INDEX($H$11:$L$19,MATCH($O14,$G$11:$G$18,0),MATCH(S$5,$H$10:$L$10,0))+I$19 -> 10 | T14: =INDEX($H$11:$L$19,MATCH($O14,$G$11:$G$18,0),MATCH(T$5,$H$10:$L$10,0))+J$19 -> 10 | U14: =K$20-(K$19+INDEX($H$11:$L$19,MATCH($O14,$G$11:$G$18,0),MATCH(U$5,$H$10:$L$10,0))) -> 39 | V14: =$L$20 -> 50 | W14: =X14*Q14 -> 27768000 | X14: =PRODUCT(R14:V14)- PRODUCT($H$19:$J$19)*U14*V14 -> 1388400 | Y14: =(X14/$X$43)*Q14 -> 0.0888576 | AA14: WD | AB14: CC | AC14: 3 | AD14: ='Game Description'!$C$22 -> 40 | AE14: =INDEX($H$11:$L$19,MATCH($AA14,$G$11:$G$19,0),MATCH(R$5,$H$10:$L$10,0)) -> 6 | AF14: =INDEX($H$11:$L$19,MATCH($AA14,$G$11:$G$19,0),MATCH(S$5,$H$10:$L$10,0)) -> 8 | AG14: =INDEX($H$11:$L$19,MATCH($AA14,$G$11:$G$19,0),MATCH(T$5,$H$10:$L$10,0)) -> 6 | AH14: =INDEX($H$11:$L$19,MATCH("CC",$G$11:$G$19,0),MATCH(AH$5,$H$10:$L$10,0)) -> 4 | AI14: =L13 -> 4 | AJ14: =AL14*$X$43 -> 921600 | AK14: =PRODUCT(AE14:AI14) -> 4608 | AL14: =IF(AD14>Q12,AD14,Q12)*(AK14/$X$43) -> 0.00294912
